Workbook
Name TaskCat: Calc!$AV$2:$AV$2001
Name TaskDone: Calc!$BG$2:$BG$2001
Name TaskDue: Calc!$AW$2:$AW$2001
Name TaskStat: Calc!$AZ$2:$AZ$2001

Sheet Instructions
B2: TASK + HABIT TRACKER
C3: Tasks · planners · decision matrix · habits · mood · gratitude · goals — dark edition
C5: SETUP
C6: Set the planner start date (habit tracker & 1-year recurring horizon), schedule interval, day start time, week start and your categories & people. Yellow cells are inputs everywhere.
C8: RECURRING SCHEDULE
C9: Set up repeating tasks ONCE (daily, weekdays, weekly, bi-weekly, monthly, quarterly, annual or once) with times, priority, importance and person. They auto-fill the Recurring Log.
C11: VARIABLE TASKS
C12: Type one-off tasks here. DAYS LEFT, DURATION and DECISION (Eisenhower) calculate automatically.
C14: RECURRING LOG
C15: Every occurrence of your recurring tasks. Update STATUS, PROGRESS and NOTES only. If you change the schedule later, re-check statuses (rows re-sort by date).
C17: TASKS FILTER
C18: All tasks (recurring + variable) in one view. Sort by due date / priority / category / person / status and filter by date range, name, priority, importance, category, status, person and decision. Click ✎ edit to jump to the exact row.
C20: DASHBOARD
... C36: Built for Microsoft Excel 365 / 2021+. Sample data is included — overwrite or delete it.

Sheet Setup
C2: SETUP
C3: Yellow cells are inputs. Categories, people, statuses & priorities feed every dropdown.
C4: GENERAL | F4: CATEGORIES | H4: PEOPLE | J4: STATUS | L4: PRIORITY
C5: Planner start date | D5: 46266 | F5: colour follows row order
C6: Today (override) | F6: Business | H6: Me | J6: Not Started | L6: 1-Urgent
C7: Today used | D7: =IF(D6="",TODAY(),D6) | F7: Personal | H7: Sam | J7: In Progress | L7: 2-High
C8: Schedule interval (min) | D8: 30 | F8: Family | H8: Lucy | J8: Waiting | L8: 3-Medium
C9: Day starts at | D9: 0.29166667 | F9: Health | H9: Tony | J9: On Hold | L9: 4-Low
C10: Week starts on | D10: Monday | F10: Social | H10: Jamie | J10: Done
F11: Birthdays | H11: Rebecca | J11: Cancelled
C12: Planner start = first day of the habit tracker & recurring-task horizon (1 year).
J17: Status & priority lists are fixed (formulas rely on them).

Sheet Dashboard
W1: CATEGORY | Y1: PERSON
B2: TODAY IS | D2: TODAY'S TASKS | G2: =IFERROR(COUNTIFS(TaskDue,Setup!$D$7,TaskDone,1)/COUNTIFS(TaskDue,Setup!$D$7,TaskStat,"<>Cancelled"),0) | J2: THIS WEEK'S TASKS | M2: =IFERROR(COUNTIFS(TaskDue,">="&$AB$3,TaskDue,"<="&($AB$3+6),TaskDone,1)/COUNTIFS(TaskDue,">="&$AB$3,TaskDue,"<="&($AB$3+6),TaskStat,"<>Cancelled"),0) | P2: TASKS SUMMARY | W2: =IF(INDEX(Setup!$F$6:$F$15,1)="","",INDEX(Setup!$F$6:$F$15,1)) | X2: =IF(W2="","",COUNTIFS(Calc!$AW$2:$AW$2001,">="&$Q$3,Calc!$AW$2:$AW$2001,"<="&$Q$4,Calc!$BH$2:$BH$2001,1,Calc!$AV$2:$AV$2001,IF($Q$5="","*",$Q$5),Calc!$BC$2:$BC$2001,IF($Q$6="","*",$Q$6),Calc!$AV$2:$AV$2001,W2)) | Y2: =IF(INDEX(Setup!$H$6:$H$15,1)="","",INDEX(Setup!$H$6:$H$15,1)) | Z2: =IF(Y2="","",COUNTIFS(Calc!$AW$2:$AW$2001,">="&$Q$3,Calc!$AW$2:$AW$2001,"<="&$Q$4,Calc!$BH$2:$BH$2001,1,Calc!$AV$2:$AV$2001,IF($Q$5="","*",$Q$5),Calc!$BC$2:$BC$2001,IF($Q$6="","*",$Q$6),Calc!$BC$2:$BC$2001,Y2))
B3: =Setup!$D$7 | E3: TASK | F3: CATEGORY | G3: PRIORITY | K3: ="TASK · week of "&TEXT($AB$3,"d mmm") | L3: CATEGORY | M3: DUE | P3: Start date | Q3: =DATE(YEAR(Setup!$D$7),MONTH(Setup!$D$7),1) | S3: blank = all | W3: =IF(INDEX(Setup!$F$6:$F$15,2)="","",INDEX(Setup!$F$6:$F$15,2)) | X3: =IF(W3="","",COUNTIFS(Calc!$AW$2:$AW$2001,">="&$Q$3,Calc!$AW$2:$AW$2001,"<="&$Q$4,Calc!$BH$2:$BH$2001,1,Calc!$AV$2:$AV$2001,IF($Q$5="","*",$Q$5),Calc!$BC$2:$BC$2001,IF($Q$6="","*",$Q$6),Calc!$AV$2:$AV$2001,W3)) | Y3: =IF(INDEX(Setup!$H$6:$H$15,2)="","",INDEX(Setup!$H$6:$H$15,2)) | Z3: =IF(Y3="","",COUNTIFS(Calc!$AW$2:$AW$2001,">="&$Q$3,Calc!$AW$2:$AW$2001,"<="&$Q$4,Calc!$BH$2:$BH$2001,1,Calc!$AV$2:$AV$2001,IF($Q$5="","*",$Q$5),Calc!$BC$2:$BC$2001,IF($Q$6="","*",$Q$6),Calc!$BC$2:$BC$2001,Y3)) | AB3: =Setup!$D$7-MOD(WEEKDAY(Setup!$D$7,IF(Setup!$D$10="Monday",2,1))-1,7)
D4: =IF(H4="","",IF(INDEX(Calc!$BG$2:$BG$2001,H4)=1,"✓","○")) | E4: =IF(H4="","",INDEX(Calc!$AU$2:$AU$2001,H4)&"") | F4: =IF(H4="","",INDEX(Calc!$AV$2:$AV$2001,H4)&"") | G4: =IF(H4="","",INDEX(Calc!$BA$2:$BA$2001,H4)&"") | H4: =IFERROR(MOD(_xlfn.AGGREGATE(15,6,Calc!$BN$2:$BN$2001/(Calc!$AW$2:$AW$2001=Setup!$D$7),1),10000),"") | J4: =IF(N4="","",IF(INDEX(Calc!$BG$2:$BG$2001,N4)=1,"✓","○")) | K4: =IF(N4="","",INDEX(Calc!$AU$2:$AU$2001,N4)&"") | L4: =IF(N4="","",INDEX(Calc!$AV$2:$AV$2001,N4)&"") | M4: =IF(N4="","",INDEX(Calc!$AW$2:$AW$2001,N4)) | N4: =IFERROR(MATCH(SMALL(Calc!$BM$2:$BM$2001,1),Calc!$BM$2:$BM$2001,0),"") | P4: End date | Q4: =EOMONTH(Setup!$D$7,0) | W4: =IF(INDEX(Setup!$F$6:$F$15,3)="","",INDEX(Setup!$F$6:$F$15,3)) | X4: =IF(W4="","",COUNTIFS(Calc!$AW$2:$AW$2001,">="&$Q$3,Calc!$AW$2:$AW$2001,"<="&$Q$4,Calc!$BH$2:$BH$2001,1,Calc!$AV$2:$AV$2001,IF($Q$5="","*",$Q$5),Calc!$BC$2:$BC$2001,IF($Q$6="","*",$Q$6),Calc!$AV$2:$AV$2001,W4)) | Y4: =IF(INDEX(Setup!$H$6:$H$15,3)="","",INDEX(Setup!$H$6:$H$15,3)) | Z4: =IF(Y4="","",COUNTIFS(Calc!$AW$2:$AW$2001,">="&$Q$3,Calc!$AW$2:$AW$2001,"<="&$Q$4,Calc!$BH$2:$BH$2001,1,Calc!$AV$2:$AV$2001,IF($Q$5="","*",$Q$5),Calc!$BC$2:$BC$2001,IF($Q$6="","*",$Q$6),Calc!$BC$2:$BC$2001,Y4))
B5: =HYPERLINK("#'Setup'!A1","› SETUP") | D5: =IF(H5="","",IF(INDEX(Calc!$BG$2:$BG$2001,H5)=1,"✓","○")) | E5: =IF(H5="","",INDEX(Calc!$AU$2:$AU$2001,H5)&"") | F5: =IF(H5="","",INDEX(Calc!$AV$2:$AV$2001,H5)&"") | G5: =IF(H5="","",INDEX(Calc!$BA$2:$BA$2001,H5)&"") | H5: =IFERROR(MOD(_xlfn.AGGREGATE(15,6,Calc!$BN$2:$BN$2001/(Calc!$AW$2:$AW$2001=Setup!$D$7),2),10000),"") | J5: =IF(N5="","",IF(INDEX(Calc!$BG$2:$BG$2001,N5)=1,"✓","○")) | K5: =IF(N5="","",INDEX(Calc!$AU$2:$AU$2001,N5)&"") | L5: =IF(N5="","",INDEX(Calc!$AV$2:$AV$2001,N5)&"") | M5: =IF(N5="","",INDEX(Calc!$AW$2:$AW$2001,N5)) | N5: =IFERROR(MATCH(SMALL(Calc!$BM$2:$BM$2001,2),Calc!$BM$2:$BM$2001,0),"") | P5: Category | W5: =IF(INDEX(Setup!$F$6:$F$15,4)="","",INDEX(Setup!$F$6:$F$15,4)) | X5: =IF(W5="","",COUNTIFS(Calc!$AW$2:$AW$2001,">="&$Q$3,Calc!$AW$2:$AW$2001,"<="&$Q$4,Calc!$BH$2:$BH$2001,1,Calc!$AV$2:$AV$2001,IF($Q$5="","*",$Q$5),Calc!$BC$2:$BC$2001,IF($Q$6="","*",$Q$6),Calc!$AV$2:$AV$2001,W5)) | Y5: =IF(INDEX(Setup!$H$6:$H$15,4)="","",INDEX(Setup!$H$6:$H$15,4)) | Z5: =IF(Y5="","",COUNTIFS(Calc!$AW$2:$AW$2001,">="&$Q$3,Calc!$AW$2:$AW$2001,"<="&$Q$4,Calc!$BH$2:$BH$2001,1,Calc!$AV$2:$AV$2001,IF($Q$5="","*",$Q$5),Calc!$BC$2:$BC$2001,IF($Q$6="","*",$Q$6),Calc!$BC$2:$BC$2001,Y5))
D6: =IF(H6="","",IF(INDEX(Calc!$BG$2:$BG$2001,H6)=1,"✓","○")) | E6: =IF(H6="","",INDEX(Calc!$AU$2:$AU$2001,H6)&"") | F6: =IF(H6="","",INDEX(Calc!$AV$2:$AV$2001,H6)&"") | G6: =IF(H6="","",INDEX(Calc!$BA$2:$BA$2001,H6)&"") | H6: =IFERROR(MOD(_xlfn.AGGREGATE(15,6,Calc!$BN$2:$BN$2001/(Calc!$AW$2:$AW$2001=Setup!$D$7),3),10000),"") | J6: =IF(N6="","",IF(INDEX(Calc!$BG$2:$BG$2001,N6)=1,"✓","○")) | K6: =IF(N6="","",INDEX(Calc!$AU$2:$AU$2001,N6)&"") | L6: =IF(N6="","",INDEX(Calc!$AV$2:$AV$2001,N6)&"") | M6: =IF(N6="","",INDEX(Calc!$AW$2:$AW$2001,N6)) | N6: =IFERROR(MATCH(SMALL(Calc!$BM$2:$BM$2001,3),Calc!$BM$2:$BM$2001,0),"") | P6: Person | W6: =IF(INDEX(Setup!$F$6:$F$15,5)="","",INDEX(Setup!$F$6:$F$15,5)) | X6: =IF(W6="","",COUNTIFS(Calc!$AW$2:$AW$2001,">="&$Q$3,Calc!$AW$2:$AW$2001,"<="&$Q$4,Calc!$BH$2:$BH$2001,1,Calc!$AV$2:$AV$2001,IF($Q$5="","*",$Q$5),Calc!$BC$2:$BC$2001,IF($Q$6="","*",$Q$6),Calc!$AV$2:$AV$2001,W6)) | Y6: =IF(INDEX(Setup!$H$6:$H$15,5)="","",INDEX(Setup!$H$6:$H$15,5)) | Z6: =IF(Y6="","",COUNTIFS(Calc!$AW$2:$AW$2001,">="&$Q$3,Calc!$AW$2:$AW$2001,"<="&$Q$4,Calc!$BH$2:$BH$2001,1,Calc!$AV$2:$AV$2001,IF($Q$5="","*",$Q$5),Calc!$BC$2:$BC$2001,IF($Q$6="","*",$Q$6),Calc!$BC$2:$BC$2001,Y6))
B7: TASK LOG + FILTER | D7: =IF(H7="","",IF(INDEX(Calc!$BG$2:$BG$2001,H7)=1,"✓","○")) | E7: =IF(H7="","",INDEX(Calc!$AU$2:$AU$2001,H7)&"") | F7: =IF(H7="","",INDEX(Calc!$AV$2:$AV$2001,H7)&"") | G7: =IF(H7="","",INDEX(Calc!$BA$2:$BA$2001,H7)&"") | H7: =IFERROR(MOD(_xlfn.AGGREGATE(15,6,Calc!$BN$2:$BN$2001/(Calc!$AW$2:$AW$2001=Setup!$D$7),4),10000),"") | J7: =IF(N7="","",IF(INDEX(Calc!$BG$2:$BG$2001,N7)=1,"✓","○")) | K7: =IF(N7="","",INDEX(Calc!$AU$2:$AU$2001,N7)&"") | L7: =IF(N7="","",INDEX(Calc!$AV$2:$AV$2001,N7)&"") | M7: =IF(N7="","",INDEX(Calc!$AW$2:$AW$2001,N7)) | N7: =IFERROR(MATCH(SMALL(Calc!$BM$2:$BM$2001,4),Calc!$BM$2:$BM$2001,0),"") | W7: =IF(INDEX(Setup!$F$6:$F$15,6)="","",INDEX(Setup!$F$6:$F$15,6)) | X7: =IF(W7="","",COUNTIFS(Calc!$AW$2:$AW$2001,">="&$Q$3,Calc!$AW$2:$AW$2001,"<="&$Q$4,Calc!$BH$2:$BH$2001,1,Calc!$AV$2:$AV$2001,IF($Q$5="","*",$Q$5),Calc!$BC$2:$BC$2001,IF($Q$6="","*",$Q$6),Calc!$AV$2:$AV$2001,W7)) | Y7: =IF(INDEX(Setup!$H$6:$H$15,6)="","",INDEX(Setup!$H$6:$H$15,6)) | Z7: =IF(Y7="","",COUNTIFS(Calc!$AW$2:$AW$2001,">="&$Q$3,Calc!$AW$2:$AW$2001,"<="&$Q$4,Calc!$BH$2:$BH$2001,1,Calc!$AV$2:$AV$2001,IF($Q$5="","*",$Q$5),Calc!$BC$2:$BC$2001,IF($Q$6="","*",$Q$6),Calc!$BC$2:$BC$2001,Y7))
B8: =HYPERLINK("#'Recurring Schedule'!A1","› Recurring Schedule") | D8: =IF(H8="","",IF(INDEX(Calc!$BG$2:$BG$2001,H8)=1,"✓","○")) | E8: =IF(H8="","",INDEX(Calc!$AU$2:$AU$2001,H8)&"") | F8: =IF(H8="","",INDEX(Calc!$AV$2:$AV$2001,H8)&"") | G8: =IF(H8="","",INDEX(Calc!$BA$2:$BA$2001,H8)&"") | H8: =IFERROR(MOD(_xlfn.AGGREGATE(15,6,Calc!$BN$2:$BN$2001/(Calc!$AW$2:$AW$2001=Setup!$D$7),5),10000),"") | J8: =IF(N8="","",IF(INDEX(Calc!$BG$2:$BG$2001,N8)=1,"✓","○")) | K8: =IF(N8="","",INDEX(Calc!$AU$2:$AU$2001,N8)&"") | L8: =IF(N8="","",INDEX(Calc!$AV$2:$AV$2001,N8)&"") | M8: =IF(N8="","",INDEX(Calc!$AW$2:$AW$2001,N8)) | N8: =IFERROR(MATCH(SMALL(Calc!$BM$2:$BM$2001,5),Calc!$BM$2:$BM$2001,0),"") | P8: DECISION MATRIX | S8: BY STATUS | W8: =IF(INDEX(Setup!$F$6:$F$15,7)="","",INDEX(Setup!$F$6:$F$15,7)) | X8: =IF(W8="","",COUNTIFS(Calc!$AW$2:$AW$2001,">="&$Q$3,Calc!$AW$2:$AW$2001,"<="&$Q$4,Calc!$BH$2:$BH$2001,1,Calc!$AV$2:$AV$2001,IF($Q$5="","*",$Q$5),Calc!$BC$2:$BC$2001,IF($Q$6="","*",$Q$6),Calc!$AV$2:$AV$2001,W8)) | Y8: =IF(INDEX(Setup!$H$6:$H$15,7)="","",INDEX(Setup!$H$6:$H$15,7)) | Z8: =IF(Y8="","",COUNTIFS(Calc!$AW$2:$AW$2001,">="&$Q$3,Calc!$AW$2:$AW$2001,"<="&$Q$4,Calc!$BH$2:$BH$2001,1,Calc!$AV$2:$AV$2001,IF($Q$5="","*",$Q$5),Calc!$BC$2:$BC$2001,IF($Q$6="","*",$Q$6),Calc!$BC$2:$BC$2001,Y8))
B9: =HYPERLINK("#'Variable Tasks'!A1","› Variable Tasks") | D9: =IF(H9="","",IF(INDEX(Calc!$BG$2:$BG$2001,H9)=1,"✓","○")) | E9: =IF(H9="","",INDEX(Calc!$AU$2:$AU$2001,H9)&"") | F9: =IF(H9="","",INDEX(Calc!$AV$2:$AV$2001,H9)&"") | G9: =IF(H9="","",INDEX(Calc!$BA$2:$BA$2001,H9)&"") | H9: =IFERROR(MOD(_xlfn.AGGREGATE(15,6,Calc!$BN$2:$BN$2001/(Calc!$AW$2:$AW$2001=Setup!$D$7),6),10000),"") | J9: =IF(N9="","",IF(INDEX(Calc!$BG$2:$BG$2001,N9)=1,"✓","○")) | K9: =IF(N9="","",INDEX(Calc!$AU$2:$AU$2001,N9)&"") | L9: =IF(N9="","",INDEX(Calc!$AV$2:$AV$2001,N9)&"") | M9: =IF(N9="","",INDEX(Calc!$AW$2:$AW$2001,N9)) | N9: =IFERROR(MATCH(SMALL(Calc!$BM$2:$BM$2001,6),Calc!$BM$2:$BM$2001,0),"") | P9: DECISION | Q9: TO DO | R9: DONE | S9: =INDEX(Setup!$J$6:$J$11,1) | U9: =COUNTIFS(Calc!$AW$2:$AW$2001,">="&$Q$3,Calc!$AW$2:$AW$2001,"<="&$Q$4,Calc!$BH$2:$BH$2001,1,Calc!$AV$2:$AV$2001,IF($Q$5="","*",$Q$5),Calc!$BC$2:$BC$2001,IF($Q$6="","*",$Q$6),Calc!$AZ$2:$AZ$2001,S9) | W9: =IF(INDEX(Setup!$F$6:$F$15,8)="","",INDEX(Setup!$F$6:$F$15,8)) | X9: =IF(W9="","",COUNTIFS(Calc!$AW$2:$AW$2001,">="&$Q$3,Calc!$AW$2:$AW$2001,"<="&$Q$4,Calc!$BH$2:$BH$2001,1,Calc!$AV$2:$AV$2001,IF($Q$5="","*",$Q$5),Calc!$BC$2:$BC$2001,IF($Q$6="","*",$Q$6),Calc!$AV$2:$AV$2001,W9)) | Y9: =IF(INDEX(Setup!$H$6:$H$15,8)="","",INDEX(Setup!$H$6:$H$15,8)) | Z9: =IF(Y9="","",COUNTIFS(Calc!$AW$2:$AW$2001,">="&$Q$3,Calc!$AW$2:$AW$2001,"<="&$Q$4,Calc!$BH$2:$BH$2001,1,Calc!$AV$2:$AV$2001,IF($Q$5="","*",$Q$5),Calc!$BC$2:$BC$2001,IF($Q$6="","*",$Q$6),Calc!$BC$2:$BC$2001,Y9))
B10: =HYPERLINK("#'Recurring Log'!A1","› Recurring Log") | D10: =IF(H10="","",IF(INDEX(Calc!$BG$2:$BG$2001,H10)=1,"✓","○")) | E10: =IF(H10="","",INDEX(Calc!$AU$2:$AU$2001,H10)&"") | F10: =IF(H10="","",INDEX(Calc!$AV$2:$AV$2001,H10)&"") | G10: =IF(H10="","",INDEX(Calc!$BA$2:$BA$2001,H10)&"") | H10: =IFERROR(MOD(_xlfn.AGGREGATE(15,6,Calc!$BN$2:$BN$2001/(Calc!$AW$2:$AW$2001=Setup!$D$7),7),10000),"") | J10: =IF(N10="","",IF(INDEX(Calc!$BG$2:$BG$2001,N10)=1,"✓","○")) | K10: =IF(N10="","",INDEX(Calc!$AU$2:$AU$2001,N10)&"") | L10: =IF(N10="","",INDEX(Calc!$AV$2:$AV$2001,N10)&"") | M10: =IF(N10="","",INDEX(Calc!$AW$2:$AW$2001,N10)) | N10: =IFERROR(MATCH(SMALL(Calc!$BM$2:$BM$2001,7),Calc!$BM$2:$BM$2001,0),"") | P10: DO FIRST | Q10: =COUNTIFS(Calc!$AW$2:$AW$2001,">="&$Q$3,Calc!$AW$2:$AW$2001,"<="&$Q$4,Calc!$BH$2:$BH$2001,1,Calc!$AV$2:$AV$2001,IF($Q$5="","*",$Q$5),Calc!$BC$2:$BC$2001,IF($Q$6="","*",$Q$6),Calc!$BD$2:$BD$2001,"DO FIRST",Calc!$BG$2:$BG$2001,0) | R10: =COUNTIFS(Calc!$AW$2:$AW$2001,">="&$Q$3,Calc!$AW$2:$AW$2001,"<="&$Q$4,Calc!$BH$2:$BH$2001,1,Calc!$AV$2:$AV$2001,IF($Q$5="","*",$Q$5),Calc!$BC$2:$BC$2001,IF($Q$6="","*",$Q$6),Calc!$BD$2:$BD$2001,"DO FIRST",Calc!$BG$2:$BG$2001,1) | S10: =INDEX(Setup!$J$6:$J$11,2) | U10: =COUNTIFS(Calc!$AW$2:$AW$2001,">="&$Q$3,Calc!$AW$2:$AW$2001,"<="&$Q$4,Calc!$BH$2:$BH$2001,1,Calc!$AV$2:$AV$2001,IF($Q$5="","*",$Q$5),Calc!$BC$2:$BC$2001,IF($Q$6="","*",$Q$6),Calc!$AZ$2:$AZ$2001,S10) | W10: =IF(INDEX(Setup!$F$6:$F$15,9)="","",INDEX(Setup!$F$6:$F$15,9)) | X10: =IF(W10="","",COUNTIFS(Calc!$AW$2:$AW$2001,">="&$Q$3,Calc!$AW$2:$AW$2001,"<="&$Q$4,Calc!$BH$2:$BH$2001,1,Calc!$AV$2:$AV$2001,IF($Q$5="","*",$Q$5),Calc!$BC$2:$BC$2001,IF($Q$6="","*",$Q$6),Calc!$AV$2:$AV$2001,W10)) | Y10: =IF(INDEX(Setup!$H$6:$H$15,9)="","",INDEX(Setup!$H$6:$H$15,9)) | Z10: =IF(Y10="","",COUNTIFS(Calc!$AW$2:$AW$2001,">="&$Q$3,Calc!$AW$2:$AW$2001,"<="&$Q$4,Calc!$BH$2:$BH$2001,1,Calc!$AV$2:$AV$2001,IF($Q$5="","*",$Q$5),Calc!$BC$2:$BC$2001,IF($Q$6="","*",$Q$6),Calc!$BC$2:$BC$2001,Y10))
B11: =HYPERLINK("#'Tasks Filter'!A1","› Tasks Filter") | D11: =IF(H11="","",IF(INDEX(Calc!$BG$2:$BG$2001,H11)=1,"✓","○")) | E11: =IF(H11="","",INDEX(Calc!$AU$2:$AU$2001,H11)&"") | F11: =IF(H11="","",INDEX(Calc!$AV$2:$AV$2001,H11)&"") | G11: =IF(H11="","",INDEX(Calc!$BA$2:$BA$2001,H11)&"") | H11: =IFERROR(MOD(_xlfn.AGGREGATE(15,6,Calc!$BN$2:$BN$2001/(Calc!$AW$2:$AW$2001=Setup!$D$7),8),10000),"") | J11: =IF(N11="","",IF(INDEX(Calc!$BG$2:$BG$2001,N11)=1,"✓","○")) | K11: =IF(N11="","",INDEX(Calc!$AU$2:$AU$2001,N11)&"") | L11: =IF(N11="","",INDEX(Calc!$AV$2:$AV$2001,N11)&"") | M11: =IF(N11="","",INDEX(Calc!$AW$2:$AW$2001,N11)) | N11: =IFERROR(MATCH(SMALL(Calc!$BM$2:$BM$2001,8),Calc!$BM$2:$BM$2001,0),"") | P11: SCHEDULE | Q11: =COUNTIFS(Calc!$AW$2:$AW$2001,">="&$Q$3,Calc!$AW$2:$AW$2001,"<="&$Q$4,Calc!$BH$2:$BH$2001,1,Calc!$AV$2:$AV$2001,IF($Q$5="","*",$Q$5),Calc!$BC$2:$BC$2001,IF($Q$6="","*",$Q$6),Calc!$BD$2:$BD$2001,"SCHEDULE",Calc!$BG$2:$BG$2001,0) | R11: =COUNTIFS(Calc!$AW$2:$AW$2001,">="&$Q$3,Calc!$AW$2:$AW$2001,"<="&$Q$4,Calc!$BH$2:$BH$2001,1,Calc!$AV$2:$AV$2001,IF($Q$5="","*",$Q$5),Calc!$BC$2:$BC$2001,IF($Q$6="","*",$Q$6),Calc!$BD$2:$BD$2001,"SCHEDULE",Calc!$BG$2:$BG$2001,1) | S11: =INDEX(Setup!$J$6:$J$11,3) | U11: =COUNTIFS(Calc!$AW$2:$AW$2001,">="&$Q$3,Calc!$AW$2:$AW$2001,"<="&$Q$4,Calc!$BH$2:$BH$2001,1,Calc!$AV$2:$AV$2001,IF($Q$5="","*",$Q$5),Calc!$BC$2:$BC$2001,IF($Q$6="","*",$Q$6),Calc!$AZ$2:$AZ$2001,S11) | W11: =IF(INDEX(Setup!$F$6:$F$15,10)="","",INDEX(Setup!$F$6:$F$15,10)) | X11: =IF(W11="","",COUNTIFS(Calc!$AW$2:$AW$2001,">="&$Q$3,Calc!$AW$2:$AW$2001,"<="&$Q$4,Calc!$BH$2:$BH$2001,1,Calc!$AV$2:$AV$2001,IF($Q$5="","*",$Q$5),Calc!$BC$2:$BC$2001,IF($Q$6="","*",$Q$6),Calc!$AV$2:$AV$2001,W11)) | Y11: =IF(INDEX(Setup!$H$6:$H$15,10)="","",INDEX(Setup!$H$6:$H$15,10)) | Z11: =IF(Y11="","",COUNTIFS(Calc!$AW$2:$AW$2001,">="&$Q$3,Calc!$AW$2:$AW$2001,"<="&$Q$4,Calc!$BH$2:$BH$2001,1,Calc!$AV$2:$AV$2001,IF($Q$5="","*",$Q$5),Calc!$BC$2:$BC$2001,IF($Q$6="","*",$Q$6),Calc!$BC$2:$BC$2001,Y11))
B12: =HYPERLINK("#'Gratitude Log'!A1","› Gratitude Log") | D12: =IF(H12="","",IF(INDEX(Calc!$BG$2:$BG$2001,H12)=1,"✓","○")) | E12: =IF(H12="","",INDEX(Calc!$AU$2:$AU$2001,H12)&"") | F12: =IF(H12="","",INDEX(Calc!$AV$2:$AV$2001,H12)&"") | G12: =IF(H12="","",INDEX(Calc!$BA$2:$BA$2001,H12)&"") | H12: =IFERROR(MOD(_xlfn.AGGREGATE(15,6,Calc!$BN$2:$BN$2001/(Calc!$AW$2:$AW$2001=Setup!$D$7),9),10000),"") | J12: =IF(N12="","",IF(INDEX(Calc!$BG$2:$BG$2001,N12)=1,"✓","○")) | K12: =IF(N12="","",INDEX(Calc!$AU$2:$AU$2001,N12)&"") | L12: =IF(N12="","",INDEX(Calc!$AV$2:$AV$2001,N12)&"") | M12: =IF(N12="","",INDEX(Calc!$AW$2:$AW$2001,N12)) | N12: =IFERROR(MATCH(SMALL(Calc!$BM$2:$BM$2001,9),Calc!$BM$2:$BM$2001,0),"") | P12: DELEGATE | Q12: =COUNTIFS(Calc!$AW$2:$AW$2001,">="&$Q$3,Calc!$AW$2:$AW$2001,"<="&$Q$4,Calc!$BH$2:$BH$2001,1,Calc!$AV$2:$AV$2001,IF($Q$5="","*",$Q$5),Calc!$BC$2:$BC$2001,IF($Q$6="","*",$Q$6),Calc!$BD$2:$BD$2001,"DELEGATE",Calc!$BG$2:$BG$2001,0) | R12: =COUNTIFS(Calc!$AW$2:$AW$2001,">="&$Q$3,Calc!$AW$2:$AW$2001,"<="&$Q$4,Calc!$BH$2:$BH$2001,1,Calc!$AV$2:$AV$2001,IF($Q$5="","*",$Q$5),Calc!$BC$2:$BC$2001,IF($Q$6="","*",$Q$6),Calc!$BD$2:$BD$2001,"DELEGATE",Calc!$BG$2:$BG$2001,1) | S12: =INDEX(Setup!$J$6:$J$11,4) | U12: =COUNTIFS(Calc!$AW$2:$AW$2001,">="&$Q$3,Calc!$AW$2:$AW$2001,"<="&$Q$4,Calc!$BH$2:$BH$2001,1,Calc!$AV$2:$AV$2001,IF($Q$5="","*",$Q$5),Calc!$BC$2:$BC$2001,IF($Q$6="","*",$Q$6),Calc!$AZ$2:$AZ$2001,S12)
B13: =HYPERLINK("#'Habit Tracker'!A1","› Habit Tracker") | D13: =IF(H13="","",IF(INDEX(Calc!$BG$2:$BG$2001,H13)=1,"✓","○")) | E13: =IF(H13="","",INDEX(Calc!$AU$2:$AU$2001,H13)&"") | F13: =IF(H13="","",INDEX(Calc!$AV$2:$AV$2001,H13)&"") | G13: =IF(H13="","",INDEX(Calc!$BA$2:$BA$2001,H13)&"") | H13: =IFERROR(MOD(_xlfn.AGGREGATE(15,6,Calc!$BN$2:$BN$2001/(Calc!$AW$2:$AW$2001=Setup!$D$7),10),10000),"") | J13: =IF(N13="","",IF(INDEX(Calc!$BG$2:$BG$2001,N13)=1,"✓","○")) | K13: =IF(N13="","",INDEX(Calc!$AU$2:$AU$2001,N13)&"") | L13: =IF(N13="","",INDEX(Calc!$AV$2:$AV$2001,N13)&"") | M13: =IF(N13="","",INDEX(Calc!$AW$2:$AW$2001,N13)) | N13: =IFERROR(MATCH(SMALL(Calc!$BM$2:$BM$2001,10),Calc!$BM$2:$BM$2001,0),"") | P13: DELETE | Q13: =COUNTIFS(Calc!$AW$2:$AW$2001,">="&$Q$3,Calc!$AW$2:$AW$2001,"<="&$Q$4,Calc!$BH$2:$BH$2001,1,Calc!$AV$2:$AV$2001,IF($Q$5="","*",$Q$5),Calc!$BC$2:$BC$2001,IF($Q$6="","*",$Q$6),Calc!$BD$2:$BD$2001,"DELETE",Calc!$BG$2:$BG$2001,0) | R13: =COUNTIFS(Calc!$AW$2:$AW$2001,">="&$Q$3,Calc!$AW$2:$AW$2001,"<="&$Q$4,Calc!$BH$2:$BH$2001,1,Calc!$AV$2:$AV$2001,IF($Q$5="","*",$Q$5),Calc!$BC$2:$BC$2001,IF($Q$6="","*",$Q$6),Calc!$BD$2:$BD$2001,"DELETE",Calc!$BG$2:$BG$2001,1) | S13: =INDEX(Setup!$J$6:$J$11,5) | U13: =COUNTIFS(Calc!$AW$2:$AW$2001,">="&$Q$3,Calc!$AW$2:$AW$2001,"<="&$Q$4,Calc!$BH$2:$BH$2001,1,Calc!$AV$2:$AV$2001,IF($Q$5="","*",$Q$5),Calc!$BC$2:$BC$2001,IF($Q$6="","*",$Q$6),Calc!$AZ$2:$AZ$2001,S13)
D14: =IF(H14="","",IF(INDEX(Calc!$BG$2:$BG$2001,H14)=1,"✓","○")) | E14: =IF(H14="","",INDEX(Calc!$AU$2:$AU$2001,H14)&"") | F14: =IF(H14="","",INDEX(Calc!$AV$2:$AV$2001,H14)&"") | G14: =IF(H14="","",INDEX(Calc!$BA$2:$BA$2001,H14)&"") | H14: =IFERROR(MOD(_xlfn.AGGREGATE(15,6,Calc!$BN$2:$BN$2001/(Calc!$AW$2:$AW$2001=Setup!$D$7),11),10000),"") | J14: =IF(N14="","",IF(INDEX(Calc!$BG$2:$BG$2001,N14)=1,"✓","○")) | K14: =IF(N14="","",INDEX(Calc!$AU$2:$AU$2001,N14)&"") | L14: =IF(N14="","",INDEX(Calc!$AV$2:$AV$2001,N14)&"") | M14: =IF(N14="","",INDEX(Calc!$AW$2:$AW$2001,N14)) | N14: =IFERROR(MATCH(SMALL(Calc!$BM$2:$BM$2001,11),Calc!$BM$2:$BM$2001,0),"") | S14: =INDEX(Setup!$J$6:$J$11,6) | U14: =COUNTIFS(Calc!$AW$2:$AW$2001,">="&$Q$3,Calc!$AW$2:$AW$2001,"<="&$Q$4,Calc!$BH$2:$BH$2001,1,Calc!$AV$2:$AV$2001,IF($Q$5="","*",$Q$5),Calc!$BC$2:$BC$2001,IF($Q$6="","*",$Q$6),Calc!$AZ$2:$AZ$2001,S14)
B15: DASHBOARDS | D15: =IF(H15="","",IF(INDEX(Calc!$BG$2:$BG$2001,H15)=1,"✓","○")) | E15: =IF(H15="","",INDEX(Calc!$AU$2:$AU$2001,H15)&"") | F15: =IF(H15="","",INDEX(Calc!$AV$2:$AV$2001,H15)&"") | G15: =IF(H15="","",INDEX(Calc!$BA$2:$BA$2001,H15)&"") | H15: =IFERROR(MOD(_xlfn.AGGREGATE(15,6,Calc!$BN$2:$BN$2001/(Calc!$AW$2:$AW$2001=Setup!$D$7),12),10000),"") | J15: =IF(N15="","",IF(INDEX(Calc!$BG$2:$BG$2001,N15)=1,"✓","○")) | K15: =IF(N15="","",INDEX(Calc!$AU$2:$AU$2001,N15)&"") | L15: =IF(N15="","",INDEX(Calc!$AV$2:$AV$2001,N15)&"") | M15: =IF(N15="","",INDEX(Calc!$AW$2:$AW$2001,N15)) | N15: =IFERROR(MATCH(SMALL(Calc!$BM$2:$BM$2001,12),Calc!$BM$2:$BM$2001,0),"")
B16: =HYPERLINK("#'Daily'!A1","› Daily") | D16: =IF(H16="","",IF(INDEX(Calc!$BG$2:$BG$2001,H16)=1,"✓","○")) | E16: =IF(H16="","",INDEX(Calc!$AU$2:$AU$2001,H16)&"") | F16: =IF(H16="","",INDEX(Calc!$AV$2:$AV$2001,H16)&"") | G16: =IF(H16="","",INDEX(Calc!$BA$2:$BA$2001,H16)&"") | H16: =IFERROR(MOD(_xlfn.AGGREGATE(15,6,Calc!$BN$2:$BN$2001/(Calc!$AW$2:$AW$2001=Setup!$D$7),13),10000),"") | J16: =IF(N16="","",IF(INDEX(Calc!$BG$2:$BG$2001,N16)=1,"✓","○")) | K16: =IF(N16="","",INDEX(Calc!$AU$2:$AU$2001,N16)&"") | L16: =IF(N16="","",INDEX(Calc!$AV$2:$AV$2001,N16)&"") | M16: =IF(N16="","",INDEX(Calc!$AW$2:$AW$2001,N16)) | N16: =IFERROR(MATCH(SMALL(Calc!$BM$2:$BM$2001,13),Calc!$BM$2:$BM$2001,0),"") | P16: TASKS BY CATEGORY
B17: =HYPERLINK("#'Weekly'!A1","› Weekly") | D17: =IF(H17="","",IF(INDEX(Calc!$BG$2:$BG$2001,H17)=1,"✓","○")) | E17: =IF(H17="","",INDEX(Calc!$AU$2:$AU$2001,H17)&"") | F17: =IF(H17="","",INDEX(Calc!$AV$2:$AV$2001,H17)&"") | G17: =IF(H17="","",INDEX(Calc!$BA$2:$BA$2001,H17)&"") | H17: =IFERROR(MOD(_xlfn.AGGREGATE(15,6,Calc!$BN$2:$BN$2001/(Calc!$AW$2:$AW$2001=Setup!$D$7),14),10000),"") | J17: =IF(N17="","",IF(INDEX(Calc!$BG$2:$BG$2001,N17)=1,"✓","○")) | K17: =IF(N17="","",INDEX(Calc!$AU$2:$AU$2001,N17)&"") | L17: =IF(N17="","",INDEX(Calc!$AV$2:$AV$2001,N17)&"") | M17: =IF(N17="","",INDEX(Calc!$AW$2:$AW$2001,N17)) | N17: =IFERROR(MATCH(SMALL(Calc!$BM$2:$BM$2001,14),Calc!$BM$2:$BM$2001,0),"")
B18: =HYPERLINK("#'Monthly'!A1","› Monthly") | J18: =IF(N18="","",IF(INDEX(Calc!$BG$2:$BG$2001,N18)=1,"✓","○")) | K18: =IF(N18="","",INDEX(Calc!$AU$2:$AU$2001,N18)&"") | L18: =IF(N18="","",INDEX(Calc!$AV$2:$AV$2001,N18)&"") | M18: =IF(N18="","",INDEX(Calc!$AW$2:$AW$2001,N18)) | N18: =IFERROR(MATCH(SMALL(Calc!$BM$2:$BM$2001,15),Calc!$BM$2:$BM$2001,0),"")
B19: =HYPERLINK("#'Decision Matrix'!A1","› Decision Matrix") | J19: =IF(N19="","",IF(INDEX(Calc!$BG$2:$BG$2001,N19)=1,"✓","○")) | K19: =IF(N19="","",INDEX(Calc!$AU$2:$AU$2001,N19)&"") | L19: =IF(N19="","",INDEX(Calc!$AV$2:$AV$2001,N19)&"") | M19: =IF(N19="","",INDEX(Calc!$AW$2:$AW$2001,N19)) | N19: =IFERROR(MATCH(SMALL(Calc!$BM$2:$BM$2001,16),Calc!$BM$2:$BM$2001,0),"")
D20: OVERDUE TASKS | G20: =COUNT(Calc!$BL$2:$BL$2001) | J20: =IF(N20="","",IF(INDEX(Calc!$BG$2:$BG$2001,N20)=1,"✓","○")) | K20: =IF(N20="","",INDEX(Calc!$AU$2:$AU$2001,N20)&"") | L20: =IF(N20="","",INDEX(Calc!$AV$2:$AV$2001,N20)&"") | M20: =IF(N20="","",INDEX(Calc!$AW$2:$AW$2001,N20)) | N20: =IFERROR(MATCH(SMALL(Calc!$BM$2:$BM$2001,17),Calc!$BM$2:$BM$2001,0),"")
B21: BONUS | E21: TASK | F21: DAYS LATE | G21: PRIORITY | J21: =IF(N21="","",IF(INDEX(Calc!$BG$2:$BG$2001,N21)=1,"✓","○")) | K21: =IF(N21="","",INDEX(Calc!$AU$2:$AU$2001,N21)&"") | L21: =IF(N21="","",INDEX(Calc!$AV$2:$AV$2001,N21)&"") | M21: =IF(N21="","",INDEX(Calc!$AW$2:$AW$2001,N21)) | N21: =IFERROR(MATCH(SMALL(Calc!$BM$2:$BM$2001,18),Calc!$BM$2:$BM$2001,0),"")
B22: =HYPERLINK("#'Goals'!A1","› Goals") | D22: =IF(I22="","",IF(INDEX(Calc!$BG$2:$BG$2001,I22)=1,"✓","○")) | E22: =IF(I22="","",INDEX(Calc!$AU$2:$AU$2001,I22)&"") | F22: =IF(I22="","",Setup!$D$7-INDEX(Calc!$AW$2:$AW$2001,I22)) | G22: =IF(I22="","",INDEX(Calc!$BA$2:$BA$2001,I22)&"") | I22: =IFERROR(MATCH(SMALL(Calc!$BL$2:$BL$2001,1),Calc!$BL$2:$BL$2001,0),"") | J22: =IF(N22="","",IF(INDEX(Calc!$BG$2:$BG$2001,N22)=1,"✓","○")) | K22: =IF(N22="","",INDEX(Calc!$AU$2:$AU$2001,N22)&"") | L22: =IF(N22="","",INDEX(Calc!$AV$2:$AV$2001,N22)&"") | M22: =IF(N22="","",INDEX(Calc!$AW$2:$AW$2001,N22)) | N22: =IFERROR(MATCH(SMALL(Calc!$BM$2:$BM$2001,19),Calc!$BM$2:$BM$2001,0),"")
B23: =HYPERLINK("#'Instructions'!A1","› Instructions") | D23: =IF(I23="","",IF(INDEX(Calc!$BG$2:$BG$2001,I23)=1,"✓","○")) | E23: =IF(I23="","",INDEX(Calc!$AU$2:$AU$2001,I23)&"") | F23: =IF(I23="","",Setup!$D$7-INDEX(Calc!$AW$2:$AW$2001,I23)) | G23: =IF(I23="","",INDEX(Calc!$BA$2:$BA$2001,I23)&"") | I23: =IFERROR(MATCH(SMALL(Calc!$BL$2:$BL$2001,2),Calc!$BL$2:$BL$2001,0),"") | J23: =IF(N23="","",IF(INDEX(Calc!$BG$2:$BG$2001,N23)=1,"✓","○")) | K23: =IF(N23="","",INDEX(Calc!$AU$2:$AU$2001,N23)&"") | L23: =IF(N23="","",INDEX(Calc!$AV$2:$AV$2001,N23)&"") | M23: =IF(N23="","",INDEX(Calc!$AW$2:$AW$2001,N23)) | N23: =IFERROR(MATCH(SMALL(Calc!$BM$2:$BM$2001,20),Calc!$BM$2:$BM$2001,0),"")
D24: =IF(I24="","",IF(INDEX(Calc!$BG$2:$BG$2001,I24)=1,"✓","○")) | E24: =IF(I24="","",INDEX(Calc!$AU$2:$AU$2001,I24)&"") | F24: =IF(I24="","",Setup!$D$7-INDEX(Calc!$AW$2:$AW$2001,I24)) | G24: =IF(I24="","",INDEX(Calc!$BA$2:$BA$2001,I24)&"") | I24: =IFERROR(MATCH(SMALL(Calc!$BL$2:$BL$2001,3),Calc!$BL$2:$BL$2001,0),"") | J24: =IF(N24="","",IF(INDEX(Calc!$BG$2:$BG$2001,N24)=1,"✓","○")) | K24: =IF(N24="","",INDEX(Calc!$AU$2:$AU$2001,N24)&"") | L24: =IF(N24="","",INDEX(Calc!$AV$2:$AV$2001,N24)&"") | M24: =IF(N24="","",INDEX(Calc!$AW$2:$AW$2001,N24)) | N24: =IFERROR(MATCH(SMALL(Calc!$BM$2:$BM$2001,21),Calc!$BM$2:$BM$2001,0),"")
D25: =IF(I25="","",IF(INDEX(Calc!$BG$2:$BG$2001,I25)=1,"✓","○")) | E25: =IF(I25="","",INDEX(Calc!$AU$2:$AU$2001,I25)&"") | F25: =IF(I25="","",Setup!$D$7-INDEX(Calc!$AW$2:$AW$2001,I25)) | G25: =IF(I25="","",INDEX(Calc!$BA$2:$BA$2001,I25)&"") | I25: =IFERROR(MATCH(SMALL(Calc!$BL$2:$BL$2001,4),Calc!$BL$2:$BL$2001,0),"") | J25: =IF(N25="","",IF(INDEX(Calc!$BG$2:$BG$2001,N25)=1,"✓","○")) | K25: =IF(N25="","",INDEX(Calc!$AU$2:$AU$2001,N25)&"") | L25: =IF(N25="","",INDEX(Calc!$AV$2:$AV$2001,N25)&"") | M25: =IF(N25="","",INDEX(Calc!$AW$2:$AW$2001,N25)) | N25: =IFERROR(MATCH(SMALL(Calc!$BM$2:$BM$2001,22),Calc!$BM$2:$BM$2001,0),"")
B26: MY TOP HABITS | D26: =IF(I26="","",IF(INDEX(Calc!$BG$2:$BG$2001,I26)=1,"✓","○")) | E26: =IF(I26="","",INDEX(Calc!$AU$2:$AU$2001,I26)&"") | F26: =IF(I26="","",Setup!$D$7-INDEX(Calc!$AW$2:$AW$2001,I26)) | G26: =IF(I26="","",INDEX(Calc!$BA$2:$BA$2001,I26)&"") | I26: =IFERROR(MATCH(SMALL(Calc!$BL$2:$BL$2001,5),Calc!$BL$2:$BL$2001,0),"") | J26: =IF(N26="","",IF(INDEX(Calc!$BG$2:$BG$2001,N26)=1,"✓","○")) | K26: =IF(N26="","",INDEX(Calc!$AU$2:$AU$2001,N26)&"") | L26: =IF(N26="","",INDEX(Calc!$AV$2:$AV$2001,N26)&"") | M26: =IF(N26="","",INDEX(Calc!$AW$2:$AW$2001,N26)) | N26: =IFERROR(MATCH(SMALL(Calc!$BM$2:$BM$2001,23),Calc!$BM$2:$BM$2001,0),"")
B27: =IF('Habit Tracker'!B9="","","1. "&'Habit Tracker'!B9) | D27: =IF(I27="","",IF(INDEX(Calc!$BG$2:$BG$2001,I27)=1,"✓","○")) | E27: =IF(I27="","",INDEX(Calc!$AU$2:$AU$2001,I27)&"") | F27: =IF(I27="","",Setup!$D$7-INDEX(Calc!$AW$2:$AW$2001,I27)) | G27: =IF(I27="","",INDEX(Calc!$BA$2:$BA$2001,I27)&"") | I27: =IFERROR(MATCH(SMALL(Calc!$BL$2:$BL$2001,6),Calc!$BL$2:$BL$2001,0),"") | J27: =IF(N27="","",IF(INDEX(Calc!$BG$2:$BG$2001,N27)=1,"✓","○")) | K27: =IF(N27="","",INDEX(Calc!$AU$2:$AU$2001,N27)&"") | L27: =IF(N27="","",INDEX(Calc!$AV$2:$AV$2001,N27)&"") | M27: =IF(N27="","",INDEX(Calc!$AW$2:$AW$2001,N27)) | N27: =IFERROR(MATCH(SMALL(Calc!$BM$2:$BM$2001,24),Calc!$BM$2:$BM$2001,0),"")
B28: =IF('Habit Tracker'!B10="","","2. "&'Habit Tracker'!B10) | D28: =IF(I28="","",IF(INDEX(Calc!$BG$2:$BG$2001,I28)=1,"✓","○")) | E28: =IF(I28="","",INDEX(Calc!$AU$2:$AU$2001,I28)&"") | F28: =IF(I28="","",Setup!$D$7-INDEX(Calc!$AW$2:$AW$2001,I28)) | G28: =IF(I28="","",INDEX(Calc!$BA$2:$BA$2001,I28)&"") | I28: =IFERROR(MATCH(SMALL(Calc!$BL$2:$BL$2001,7),Calc!$BL$2:$BL$2001,0),"") | J28: =IF(N28="","",IF(INDEX(Calc!$BG$2:$BG$2001,N28)=1,"✓","○")) | K28: =IF(N28="","",INDEX(Calc!$AU$2:$AU$2001,N28)&"") | L28: =IF(N28="","",INDEX(Calc!$AV$2:$AV$2001,N28)&"") | M28: =IF(N28="","",INDEX(Calc!$AW$2:$AW$2001,N28)) | N28: =IFERROR(MATCH(SMALL(Calc!$BM$2:$BM$2001,25),Calc!$BM$2:$BM$2001,0),"")
B29: =IF('Habit Tracker'!B11="","","3. "&'Habit Tracker'!B11) | D29: =IF(I29="","",IF(INDEX(Calc!$BG$2:$BG$2001,I29)=1,"✓","○")) | E29: =IF(I29="","",INDEX(Calc!$AU$2:$AU$2001,I29)&"") | F29: =IF(I29="","",Setup!$D$7-INDEX(Calc!$AW$2:$AW$2001,I29)) | G29: =IF(I29="","",INDEX(Calc!$BA$2:$BA$2001,I29)&"") | I29: =IFERROR(MATCH(SMALL(Calc!$BL$2:$BL$2001,8),Calc!$BL$2:$BL$2001,0),"") | J29: =IF(N29="","",IF(INDEX(Calc!$BG$2:$BG$2001,N29)=1,"✓","○")) | K29: =IF(N29="","",INDEX(Calc!$AU$2:$AU$2001,N29)&"") | L29: =IF(N29="","",INDEX(Calc!$AV$2:$AV$2001,N29)&"") | M29: =IF(N29="","",INDEX(Calc!$AW$2:$AW$2001,N29)) | N29: =IFERROR(MATCH(SMALL(Calc!$BM$2:$BM$2001,26),Calc!$BM$2:$BM$2001,0),"")
B30: =IF('Habit Tracker'!B12="","","4. "&'Habit Tracker'!B12) | D30: =IF(I30="","",IF(INDEX(Calc!$BG$2:$BG$2001,I30)=1,"✓","○")) | E30: =IF(I30="","",INDEX(Calc!$AU$2:$AU$2001,I30)&"") | F30: =IF(I30="","",Setup!$D$7-INDEX(Calc!$AW$2:$AW$2001,I30)) | G30: =IF(I30="","",INDEX(Calc!$BA$2:$BA$2001,I30)&"") | I30: =IFERROR(MATCH(SMALL(Calc!$BL$2:$BL$2001,9),Calc!$BL$2:$BL$2001,0),"") | J30: =IF(N30="","",IF(INDEX(Calc!$BG$2:$BG$2001,N30)=1,"✓","○")) | K30: =IF(N30="","",INDEX(Calc!$AU$2:$AU$2001,N30)&"") | L30: =IF(N30="","",INDEX(Calc!$AV$2:$AV$2001,N30)&"") | M30: =IF(N30="","",INDEX(Calc!$AW$2:$AW$2001,N30)) | N30: =IFERROR(MATCH(SMALL(Calc!$BM$2:$BM$2001,27),Calc!$BM$2:$BM$2001,0),"")
B31: =IF('Habit Tracker'!B13="","","5. "&'Habit Tracker'!B13) | D31: =IF(I31="","",IF(INDEX(Calc!$BG$2:$BG$2001,I31)=1,"✓","○")) | E31: =IF(I31="","",INDEX(Calc!$AU$2:$AU$2001,I31)&"") | F31: =IF(I31="","",Setup!$D$7-INDEX(Calc!$AW$2:$AW$2001,I31)) | G31: =IF(I31="","",INDEX(Calc!$BA$2:$BA$2001,I31)&"") | I31: =IFERROR(MATCH(SMALL(Calc!$BL$2:$BL$2001,10),Calc!$BL$2:$BL$2001,0),"") | J31: =IF(N31="","",IF(INDEX(Calc!$BG$2:$BG$2001,N31)=1,"✓","○")) | K31: =IF(N31="","",INDEX(Calc!$AU$2:$AU$2001,N31)&"") | L31: =IF(N31="","",INDEX(Calc!$AV$2:$AV$2001,N31)&"") | M31: =IF(N31="","",INDEX(Calc!$AW$2:$AW$2001,N31)) | N31: =IFERROR(MATCH(SMALL(Calc!$BM$2:$BM$2001,28),Calc!$BM$2:$BM$2001,0),"") | P31: TASKS BY PERSON
B32: =IF('Habit Tracker'!B14="","","6. "&'Habit Tracker'!B14) | D32: =IF(I32="","",IF(INDEX(Calc!$BG$2:$BG$2001,I32)=1,"✓","○")) | E32: =IF(I32="","",INDEX(Calc!$AU$2:$AU$2001,I32)&"") | F32: =IF(I32="","",Setup!$D$7-INDEX(Calc!$AW$2:$AW$2001,I32)) | G32: =IF(I32="","",INDEX(Calc!$BA$2:$BA$2001,I32)&"") | I32: =IFERROR(MATCH(SMALL(Calc!$BL$2:$BL$2001,11),Calc!$BL$2:$BL$2001,0),"") | J32: =IF(N32="","",IF(INDEX(Calc!$BG$2:$BG$2001,N32)=1,"✓","○")) | K32: =IF(N32="","",INDEX(Calc!$AU$2:$AU$2001,N32)&"") | L32: =IF(N32="","",INDEX(Calc!$AV$2:$AV$2001,N32)&"") | M32: =IF(N32="","",INDEX(Calc!$AW$2:$AW$2001,N32)) | N32: =IFERROR(MATCH(SMALL(Calc!$BM$2:$BM$2001,29),Calc!$BM$2:$BM$2001,0),"")
B33: =IF('Habit Tracker'!B15="","","7. "&'Habit Tracker'!B15) | D33: =IF(I33="","",IF(INDEX(Calc!$BG$2:$BG$2001,I33)=1,"✓","○")) | E33: =IF(I33="","",INDEX(Calc!$AU$2:$AU$2001,I33)&"") | F33: =IF(I33="","",Setup!$D$7-INDEX(Calc!$AW$2:$AW$2001,I33)) | G33: =IF(I33="","",INDEX(Calc!$BA$2:$BA$2001,I33)&"") | I33: =IFERROR(MATCH(SMALL(Calc!$BL$2:$BL$2001,12),Calc!$BL$2:$BL$2001,0),"") | J33: =IF(N33="","",IF(INDEX(Calc!$BG$2:$BG$2001,N33)=1,"✓","○")) | K33: =IF(N33="","",INDEX(Calc!$AU$2:$AU$2001,N33)&"") | L33: =IF(N33="","",INDEX(Calc!$AV$2:$AV$2001,N33)&"") | M33: =IF(N33="","",INDEX(Calc!$AW$2:$AW$2001,N33)) | N33: =IFERROR(MATCH(SMALL(Calc!$BM$2:$BM$2001,30),Calc!$BM$2:$BM$2001,0),"")
B34: =IF('Habit Tracker'!B16="","","8. "&'Habit Tracker'!B16)
D36: DECISION MATRIX — TO DO vs DONE

Sheet Recurring Schedule
B2: RECURRING TASK SCHEDULE
B3: Set up repeating tasks ONCE — they auto-fill the Recurring Log, Tasks Filter, Dashboard, Daily, Weekly, Monthly & Decision Matrix for a full year.
B4: RECURRING TASKS
B5: # | C5: TASK | D5: CATEGORY | E5: FREQUENCY | F5: 1ST DATE | G5: END DATE | H5: START TIME | I5: END TIME | J5: PRIORITY | K5: IMPORTANT | L5: PERSON | M5: NOTES
B6: 1 | C6: Yoga | D6: Personal | E6: Daily | F6: 46293 | H6: 0.3125 | I6: 0.33333333 | J6: 3-Medium | K6: ✓ | L6: Me | N6: =IFERROR(VLOOKUP(E6,Lists!$A$2:$C$9,2,0),0) | O6: =IFERROR(VLOOKUP(E6,Lists!$A$2:$C$9,3,0),0) | P6: =IF(G6="",Setup!$D$5+365,MIN(G6,Setup!$D$5+365))
B7: 2 | C7: Meditate | D7: Health | E7: Weekdays | F7: 46293 | H7: 0.35416667 | I7: 0.36458333 | J7: 4-Low | L7: Me | N7: =IFERROR(VLOOKUP(E7,Lists!$A$2:$C$9,2,0),0) | O7: =IFERROR(VLOOKUP(E7,Lists!$A$2:$C$9,3,0),0) | P7: =IF(G7="",Setup!$D$5+365,MIN(G7,Setup!$D$5+365))
B8: 3 | C8: Monday Meeting | D8: Business | E8: Weekly | F8: 46293 | H8: 0.375 | I8: 0.41666667 | J8: 2-High | K8: ✓ | L8: Me | N8: =IFERROR(VLOOKUP(E8,Lists!$A$2:$C$9,2,0),0) | O8: =IFERROR(VLOOKUP(E8,Lists!$A$2:$C$9,3,0),0) | P8: =IF(G8="",Setup!$D$5+365,MIN(G8,Setup!$D$5+365))
B9: 4 | C9: Write project proposal | D9: Business | E9: Weekly | F9: 46295 | G9: 46387 | H9: 0.38541667 | I9: 0.45833333 | J9: 1-Urgent | K9: ✓ | L9: Me | N9: =IFERROR(VLOOKUP(E9,Lists!$A$2:$C$9,2,0),0) | O9: =IFERROR(VLOOKUP(E9,Lists!$A$2:$C$9,3,0),0) | P9: =IF(G9="",Setup!$D$5+365,MIN(G9,Setup!$D$5+365))
B10: 5 | C10: Pilates | D10: Health | E10: Weekly | F10: 46296 | H10: 0.75 | I10: 0.79166667 | J10: 3-Medium | K10: ✓ | L10: Me | N10: =IFERROR(VLOOKUP(E10,Lists!$A$2:$C$9,2,0),0) | O10: =IFERROR(VLOOKUP(E10,Lists!$A$2:$C$9,3,0),0) | P10: =IF(G10="",Setup!$D$5+365,MIN(G10,Setup!$D$5+365))
B11: 6 | C11: Amy's Soccer Game | D11: Family | E11: Weekly | F11: 46298 | G11: 46375 | H11: 0.41666667 | I11: 0.47916667 | J11: 2-High | K11: ✓ | L11: Sam | N11: =IFERROR(VLOOKUP(E11,Lists!$A$2:$C$9,2,0),0) | O11: =IFERROR(VLOOKUP(E11,Lists!$A$2:$C$9,3,0),0) | P11: =IF(G11="",Setup!$D$5+365,MIN(G11,Setup!$D$5+365))
B12: 7 | C12: Water Plants | D12: Personal | E12: Weekly | F12: 46299 | H12: 0.70833333 | I12: 0.71875 | J12: 4-Low | L12: Lucy | N12: =IFERROR(VLOOKUP(E12,Lists!$A$2:$C$9,2,0),0) | O12: =IFERROR(VLOOKUP(E12,Lists!$A$2:$C$9,3,0),0) | P12: =IF(G12="",Setup!$D$5+365,MIN(G12,Setup!$D$5+365))
B13: 8 | C13: Friday task review | D13: Business | E13: Weekly | F13: 46297 | H13: 0.66666667 | I13: 0.6875 | J13: 3-Medium | L13: Me | N13: =IFERROR(VLOOKUP(E13,Lists!$A$2:$C$9,2,0),0) | O13: =IFERROR(VLOOKUP(E13,Lists!$A$2:$C$9,3,0),0) | P13: =IF(G13="",Setup!$D$5+365,MIN(G13,Setup!$D$5+365))
B14: 9 | C14: Date Night | D14: Family | E14: Bi-weekly | F14: 46298 | H14: 0.79166667 | I14: 0.875 | J14: 2-High | K14: ✓ | L14: Me | N14: =IFERROR(VLOOKUP(E14,Lists!$A$2:$C$9,2,0),0) | O14: =IFERROR(VLOOKUP(E14,Lists!$A$2:$C$9,3,0),0) | P14: =IF(G14="",Setup!$D$5+365,MIN(G14,Setup!$D$5+365))
B15: 10 | C15: Monthly goal planning | D15: Personal | E15: Monthly | F15: 46296 | H15: 0.83333333 | I15: 0.875 | J15: 2-High | K15: ✓ | L15: Me | N15: =IFERROR(VLOOKUP(E15,Lists!$A$2:$C$9,2,0),0) | O15: =IFERROR(VLOOKUP(E15,Lists!$A$2:$C$9,3,0),0) | P15: =IF(G15="",Setup!$D$5+365,MIN(G15,Setup!$D$5+365))
B16: 11 | C16: Pay credit card | D16: Personal | E16: Monthly | F16: 46305 | J16: 1-Urgent | K16: ✓ | L16: Me | N16: =IFERROR(VLOOKUP(E16,Lists!$A$2:$C$9,2,0),0) | O16: =IFERROR(VLOOKUP(E16,Lists!$A$2:$C$9,3,0),0) | P16: =IF(G16="",Setup!$D$5+365,MIN(G16,Setup!$D$5+365))
B17: 12 | C17: Dentist check-up | D17: Health | E17: Quarterly | F17: 46338 | H17: 0.58333333 | I17: 0.625 | J17: 3-Medium | K17: ✓ | L17: Me | N17: =IFERROR(VLOOKUP(E17,Lists!$A$2:$C$9,2,0),0) | O17: =IFERROR(VLOOKUP(E17,Lists!$A$2:$C$9,3,0),0) | P17: =IF(G17="",Setup!$D$5+365,MIN(G17,Setup!$D$5+365))
B18: 13 | N18: =IFERROR(VLOOKUP(E18,Lists!$A$2:$C$9,2,0),0) | O18: =IFERROR(VLOOKUP(E18,Lists!$A$2:$C$9,3,0),0) | P18: =IF(G18="",Setup!$D$5+365,MIN(G18,Setup!$D$5+365))
B19: 14 | N19: =IFERROR(VLOOKUP(E19,Lists!$A$2:$C$9,2,0),0) | O19: =IFERROR(VLOOKUP(E19,Lists!$A$2:$C$9,3,0),0) | P19: =IF(G19="",Setup!$D$5+365,MIN(G19,Setup!$D$5+365))
B20: 15 | N20: =IFERROR(VLOOKUP(E20,Lists!$A$2:$C$9,2,0),0) | O20: =IFERROR(VLOOKUP(E20,Lists!$A$2:$C$9,3,0),0) | P20: =IF(G20="",Setup!$D$5+365,MIN(G20,Setup!$D$5+365))
B21: 16 | N21: =IFERROR(VLOOKUP(E21,Lists!$A$2:$C$9,2,0),0) | O21: =IFERROR(VLOOKUP(E21,Lists!$A$2:$C$9,3,0),0) | P21: =IF(G21="",Setup!$D$5+365,MIN(G21,Setup!$D$5+365))
B22: 17 | N22: =IFERROR(VLOOKUP(E22,Lists!$A$2:$C$9,2,0),0) | O22: =IFERROR(VLOOKUP(E22,Lists!$A$2:$C$9,3,0),0) | P22: =IF(G22="",Setup!$D$5+365,MIN(G22,Setup!$D$5+365))
B23: 18 | N23: =IFERROR(VLOOKUP(E23,Lists!$A$2:$C$9,2,0),0) | O23: =IFERROR(VLOOKUP(E23,Lists!$A$2:$C$9,3,0),0) | P23: =IF(G23="",Setup!$D$5+365,MIN(G23,Setup!$D$5+365))
B24: 19 | N24: =IFERROR(VLOOKUP(E24,Lists!$A$2:$C$9,2,0),0) | O24: =IFERROR(VLOOKUP(E24,Lists!$A$2:$C$9,3,0),0) | P24: =IF(G24="",Setup!$D$5+365,MIN(G24,Setup!$D$5+365))
B25: 20 | N25: =IFERROR(VLOOKUP(E25,Lists!$A$2:$C$9,2,0),0) | O25: =IFERROR(VLOOKUP(E25,Lists!$A$2:$C$9,3,0),0) | P25: =IF(G25="",Setup!$D$5+365,MIN(G25,Setup!$D$5+365))
B26: 21 | N26: =IFERROR(VLOOKUP(E26,Lists!$A$2:$C$9,2,0),0) | O26: =IFERROR(VLOOKUP(E26,Lists!$A$2:$C$9,3,0),0) | P26: =IF(G26="",Setup!$D$5+365,MIN(G26,Setup!$D$5+365))
B27: 22 | N27: =IFERROR(VLOOKUP(E27,Lists!$A$2:$C$9,2,0),0) | O27: =IFERROR(VLOOKUP(E27,Lists!$A$2:$C$9,3,0),0) | P27: =IF(G27="",Setup!$D$5+365,MIN(G27,Setup!$D$5+365))
B28: 23 | N28: =IFERROR(VLOOKUP(E28,Lists!$A$2:$C$9,2,0),0) | O28: =IFERROR(VLOOKUP(E28,Lists!$A$2:$C$9,3,0),0) | P28: =IF(G28="",Setup!$D$5+365,MIN(G28,Setup!$D$5+365))
B29: 24 | N29: =IFERROR(VLOOKUP(E29,Lists!$A$2:$C$9,2,0),0) | O29: =IFERROR(VLOOKUP(E29,Lists!$A$2:$C$9,3,0),0) | P29: =IF(G29="",Setup!$D$5+365,MIN(G29,Setup!$D$5+365))
... B45: 40 | N45: =IFERROR(VLOOKUP(E45,Lists!$A$2:$C$9,2,0),0) | O45: =IFERROR(VLOOKUP(E45,Lists!$A$2:$C$9,3,0),0) | P45: =IF(G45="",Setup!$D$5+365,MIN(G45,Setup!$D$5+365))

Sheet Variable Tasks
B2: VARIABLE TASKS
B3: One-off tasks — type them here. Pink = overdue · purple = due today · grey = done.
B4: TASK DETAILS | E4: SCHEDULE | J4: STATUS & PROGRESS | L4: EISENHOWER MATRIX | P4: NOTES
B5: # | C5: TASK | D5: CATEGORY | E5: DUE DATE | F5: DAYS LEFT | G5: START | H5: END | I5: DURATION | J5: STATUS | K5: PROGRESS | L5: PRIORITY | M5: IMPORTANT | N5: DELEGATE TO | O5: DECISION | P5: NOTES
B6: 1 | C6: Respond to emails | D6: Business | E6: 46285 | F6: =IF(OR(C6="",E6=""),"",E6-Setup!$D$7) | G6: 0.375 | H6: 0.44791667 | I6: =IF(OR(G6="",H6=""),"",TRIM(IF(HOUR(H6-G6)>0,HOUR(H6-G6)&" hr ","")&IF(MINUTE(H6-G6)>0,MINUTE(H6-G6)&" min",""))) | J6: Not Started | L6: 1-Urgent | N6: Me | O6: =IF(C6="","",IF(AND(OR(L6="1-Urgent",L6="2-High"),M6="✓"),"DO FIRST",IF(M6="✓","SCHEDULE",IF(OR(L6="1-Urgent",L6="2-High"),"DELEGATE","DELETE"))))
B7: 2 | C7: Conduct market research | D7: Business | E7: 46286 | F7: =IF(OR(C7="",E7=""),"",E7-Setup!$D$7) | G7: 0.6875 | H7: 0.72916667 | I7: =IF(OR(G7="",H7=""),"",TRIM(IF(HOUR(H7-G7)>0,HOUR(H7-G7)&" hr ","")&IF(MINUTE(H7-G7)>0,MINUTE(H7-G7)&" min",""))) | J7: Not Started | L7: 2-High | N7: Me | O7: =IF(C7="","",IF(AND(OR(L7="1-Urgent",L7="2-High"),M7="✓"),"DO FIRST",IF(M7="✓","SCHEDULE",IF(OR(L7="1-Urgent",L7="2-High"),"DELEGATE","DELETE"))))
B8: 3 | C8: Organize project files | D8: Business | E8: 46287 | F8: =IF(OR(C8="",E8=""),"",E8-Setup!$D$7) | G8: 0.5625 | H8: 0.64583333 | I8: =IF(OR(G8="",H8=""),"",TRIM(IF(HOUR(H8-G8)>0,HOUR(H8-G8)&" hr ","")&IF(MINUTE(H8-G8)>0,MINUTE(H8-G8)&" min",""))) | J8: Done | K8: 1 | L8: 2-High | N8: Rebecca | O8: =IF(C8="","",IF(AND(OR(L8="1-Urgent",L8="2-High"),M8="✓"),"DO FIRST",IF(M8="✓","SCHEDULE",IF(OR(L8="1-Urgent",L8="2-High"),"DELEGATE","DELETE"))))
B9: 4 | C9: Brief Amanda | D9: Business | E9: 46288 | F9: =IF(OR(C9="",E9=""),"",E9-Setup!$D$7) | G9: 0.625 | H9: 0.65625 | I9: =IF(OR(G9="",H9=""),"",TRIM(IF(HOUR(H9-G9)>0,HOUR(H9-G9)&" hr ","")&IF(MINUTE(H9-G9)>0,MINUTE(H9-G9)&" min",""))) | J9: Done | K9: 1 | L9: 3-Medium | M9: ✓ | N9: Tony | O9: =IF(C9="","",IF(AND(OR(L9="1-Urgent",L9="2-High"),M9="✓"),"DO FIRST",IF(M9="✓","SCHEDULE",IF(OR(L9="1-Urgent",L9="2-High"),"DELEGATE","DELETE"))))
B10: 5 | C10: Track weekly goals | D10: Personal | E10: 46290 | F10: =IF(OR(C10="",E10=""),"",E10-Setup!$D$7) | G10: 0.47916667 | H10: 0.5625 | I10: =IF(OR(G10="",H10=""),"",TRIM(IF(HOUR(H10-G10)>0,HOUR(H10-G10)&" hr ","")&IF(MINUTE(H10-G10)>0,MINUTE(H10-G10)&" min",""))) | J10: In Progress | K10: 0.8 | L10: 2-High | M10: ✓ | N10: Me | O10: =IF(C10="","",IF(AND(OR(L10="1-Urgent",L10="2-High"),M10="✓"),"DO FIRST",IF(M10="✓","SCHEDULE",IF(OR(L10="1-Urgent",L10="2-High"),"DELEGATE","DELETE"))))
B11: 6 | C11: Coffee with Alex | D11: Social | E11: 46291 | F11: =IF(OR(C11="",E11=""),"",E11-Setup!$D$7) | I11: =IF(OR(G11="",H11=""),"",TRIM(IF(HOUR(H11-G11)>0,HOUR(H11-G11)&" hr ","")&IF(MINUTE(H11-G11)>0,MINUTE(H11-G11)&" min",""))) | J11: Done | K11: 1 | L11: 2-High | M11: ✓ | N11: Rebecca | O11: =IF(C11="","",IF(AND(OR(L11="1-Urgent",L11="2-High"),M11="✓"),"DO FIRST",IF(M11="✓","SCHEDULE",IF(OR(L11="1-Urgent",L11="2-High"),"DELEGATE","DELETE"))))
B12: 7 | C12: Declutter desk | D12: Personal | E12: 46292 | F12: =IF(OR(C12="",E12=""),"",E12-Setup!$D$7) | G12: 0.6875 | H12: 0.77083333 | I12: =IF(OR(G12="",H12=""),"",TRIM(IF(HOUR(H12-G12)>0,HOUR(H12-G12)&" hr ","")&IF(MINUTE(H12-G12)>0,MINUTE(H12-G12)&" min",""))) | J12: Not Started | L12: 3-Medium | N12: Rebecca | O12: =IF(C12="","",IF(AND(OR(L12="1-Urgent",L12="2-High"),M12="✓"),"DO FIRST",IF(M12="✓","SCHEDULE",IF(OR(L12="1-Urgent",L12="2-High"),"DELEGATE","DELETE"))))
B13: 8 | C13: Review client feedback | D13: Business | E13: 46294 | F13: =IF(OR(C13="",E13=""),"",E13-Setup!$D$7) | G13: 0.54166667 | H13: 0.61458333 | I13: =IF(OR(G13="",H13=""),"",TRIM(IF(HOUR(H13-G13)>0,HOUR(H13-G13)&" hr ","")&IF(MINUTE(H13-G13)>0,MINUTE(H13-G13)&" min",""))) | J13: Not Started | L13: 2-High | N13: Jamie | O13: =IF(C13="","",IF(AND(OR(L13="1-Urgent",L13="2-High"),M13="✓"),"DO FIRST",IF(M13="✓","SCHEDULE",IF(OR(L13="1-Urgent",L13="2-High"),"DELEGATE","DELETE"))))
B14: 9 | C14: Analyze sales data | D14: Business | E14: 46295 | F14: =IF(OR(C14="",E14=""),"",E14-Setup!$D$7) | G14: 0.54166667 | H14: 0.61458333 | I14: =IF(OR(G14="",H14=""),"",TRIM(IF(HOUR(H14-G14)>0,HOUR(H14-G14)&" hr ","")&IF(MINUTE(H14-G14)>0,MINUTE(H14-G14)&" min",""))) | L14: 3-Medium | M14: ✓ | N14: Me | O14: =IF(C14="","",IF(AND(OR(L14="1-Urgent",L14="2-High"),M14="✓"),"DO FIRST",IF(M14="✓","SCHEDULE",IF(OR(L14="1-Urgent",L14="2-High"),"DELEGATE","DELETE"))))
B15: 10 | C15: Take Sam to Dentist | D15: Family | E15: 46296 | F15: =IF(OR(C15="",E15=""),"",E15-Setup!$D$7) | G15: 0.47916667 | H15: 0.47916667 | I15: =IF(OR(G15="",H15=""),"",TRIM(IF(HOUR(H15-G15)>0,HOUR(H15-G15)&" hr ","")&IF(MINUTE(H15-G15)>0,MINUTE(H15-G15)&" min",""))) | J15: In Progress | K15: 0.25 | L15: 4-Low | M15: ✓ | N15: Me | O15: =IF(C15="","",IF(AND(OR(L15="1-Urgent",L15="2-High"),M15="✓"),"DO FIRST",IF(M15="✓","SCHEDULE",IF(OR(L15="1-Urgent",L15="2-High"),"DELEGATE","DELETE"))))
B16: 11 | C16: Thyroid Check | D16: Health | E16: 46298 | F16: =IF(OR(C16="",E16=""),"",E16-Setup!$D$7) | G16: 0.4375 | H16: 0.52083333 | I16: =IF(OR(G16="",H16=""),"",TRIM(IF(HOUR(H16-G16)>0,HOUR(H16-G16)&" hr ","")&IF(MINUTE(H16-G16)>0,MINUTE(H16-G16)&" min",""))) | J16: Not Started | L16: 1-Urgent | M16: ✓ | N16: Jamie | O16: =IF(C16="","",IF(AND(OR(L16="1-Urgent",L16="2-High"),M16="✓"),"DO FIRST",IF(M16="✓","SCHEDULE",IF(OR(L16="1-Urgent",L16="2-High"),"DELEGATE","DELETE"))))
B17: 12 | C17: Design product logo | D17: Business | E17: 46299 | F17: =IF(OR(C17="",E17=""),"",E17-Setup!$D$7) | G17: 0.5625 | H17: 0.60416667 | I17: =IF(OR(G17="",H17=""),"",TRIM(IF(HOUR(H17-G17)>0,HOUR(H17-G17)&" hr ","")&IF(MINUTE(H17-G17)>0,MINUTE(H17-G17)&" min",""))) | J17: Not Started | L17: 1-Urgent | M17: ✓ | N17: Me | O17: =IF(C17="","",IF(AND(OR(L17="1-Urgent",L17="2-High"),M17="✓"),"DO FIRST",IF(M17="✓","SCHEDULE",IF(OR(L17="1-Urgent",L17="2-High"),"DELEGATE","DELETE"))))
B18: 13 | C18: Draft blog post | D18: Business | E18: 46300 | F18: =IF(OR(C18="",E18=""),"",E18-Setup!$D$7) | G18: 0.54166667 | H18: 0.61458333 | I18: =IF(OR(G18="",H18=""),"",TRIM(IF(HOUR(H18-G18)>0,HOUR(H18-G18)&" hr ","")&IF(MINUTE(H18-G18)>0,MINUTE(H18-G18)&" min",""))) | J18: Waiting | K18: 0.5 | L18: 3-Medium | M18: ✓ | N18: Me | O18: =IF(C18="","",IF(AND(OR(L18="1-Urgent",L18="2-High"),M18="✓"),"DO FIRST",IF(M18="✓","SCHEDULE",IF(OR(L18="1-Urgent",L18="2-High"),"DELEGATE","DELETE"))))
B19: 14 | C19: Dinner with Amy | D19: Social | E19: 46301 | F19: =IF(OR(C19="",E19=""),"",E19-Setup!$D$7) | G19: 0.6875 | H19: 0.72916667 | I19: =IF(OR(G19="",H19=""),"",TRIM(IF(HOUR(H19-G19)>0,HOUR(H19-G19)&" hr ","")&IF(MINUTE(H19-G19)>0,MINUTE(H19-G19)&" min",""))) | J19: In Progress | K19: 0.4 | L19: 4-Low | M19: ✓ | N19: Me | O19: =IF(C19="","",IF(AND(OR(L19="1-Urgent",L19="2-High"),M19="✓"),"DO FIRST",IF(M19="✓","SCHEDULE",IF(OR(L19="1-Urgent",L19="2-High"),"DELEGATE","DELETE"))))
B20: 15 | C20: Plan weekend away | D20: Family | E20: 46303 | F20: =IF(OR(C20="",E20=""),"",E20-Setup!$D$7) | G20: 0.6875 | H20: 0.6875 | I20: =IF(OR(G20="",H20=""),"",TRIM(IF(HOUR(H20-G20)>0,HOUR(H20-G20)&" hr ","")&IF(MINUTE(H20-G20)>0,MINUTE(H20-G20)&" min",""))) | L20: 4-Low | N20: Lucy | O20: =IF(C20="","",IF(AND(OR(L20="1-Urgent",L20="2-High"),M20="✓"),"DO FIRST",IF(M20="✓","SCHEDULE",IF(OR(L20="1-Urgent",L20="2-High"),"DELEGATE","DELETE"))))
B21: 16 | C21: Clean kitchen | D21: Family | E21: 46304 | F21: =IF(OR(C21="",E21=""),"",E21-Setup!$D$7) | G21: 0.4375 | H21: 0.47916667 | I21: =IF(OR(G21="",H21=""),"",TRIM(IF(HOUR(H21-G21)>0,HOUR(H21-G21)&" hr ","")&IF(MINUTE(H21-G21)>0,MINUTE(H21-G21)&" min",""))) | L21: 3-Medium | M21: ✓ | N21: Rebecca | O21: =IF(C21="","",IF(AND(OR(L21="1-Urgent",L21="2-High"),M21="✓"),"DO FIRST",IF(M21="✓","SCHEDULE",IF(OR(L21="1-Urgent",L21="2-High"),"DELEGATE","DELETE"))))
B22: 17 | C22: Family Lunch | D22: Family | E22: 46305 | F22: =IF(OR(C22="",E22=""),"",E22-Setup!$D$7) | G22: 0.5625 | H22: 0.5625 | I22: =IF(OR(G22="",H22=""),"",TRIM(IF(HOUR(H22-G22)>0,HOUR(H22-G22)&" hr ","")&IF(MINUTE(H22-G22)>0,MINUTE(H22-G22)&" min",""))) | J22: Waiting | K22: 0.5 | L22: 1-Urgent | N22: Jamie | O22: =IF(C22="","",IF(AND(OR(L22="1-Urgent",L22="2-High"),M22="✓"),"DO FIRST",IF(M22="✓","SCHEDULE",IF(OR(L22="1-Urgent",L22="2-High"),"DELEGATE","DELETE"))))
B23: 18 | C23: Madison's Bday | D23: Birthdays | E23: 46307 | F23: =IF(OR(C23="",E23=""),"",E23-Setup!$D$7) | G23: 0.47916667 | H23: 0.52083333 | I23: =IF(OR(G23="",H23=""),"",TRIM(IF(HOUR(H23-G23)>0,HOUR(H23-G23)&" hr ","")&IF(MINUTE(H23-G23)>0,MINUTE(H23-G23)&" min",""))) | L23: 4-Low | M23: ✓ | N23: Me | O23: =IF(C23="","",IF(AND(OR(L23="1-Urgent",L23="2-High"),M23="✓"),"DO FIRST",IF(M23="✓","SCHEDULE",IF(OR(L23="1-Urgent",L23="2-High"),"DELEGATE","DELETE"))))
B24: 19 | C24: Client follow-up calls | D24: Business | E24: 46308 | F24: =IF(OR(C24="",E24=""),"",E24-Setup!$D$7) | G24: 0.625 | H24: 0.69791667 | I24: =IF(OR(G24="",H24=""),"",TRIM(IF(HOUR(H24-G24)>0,HOUR(H24-G24)&" hr ","")&IF(MINUTE(H24-G24)>0,MINUTE(H24-G24)&" min",""))) | J24: In Progress | K24: 0.8 | L24: 3-Medium | N24: Jamie | O24: =IF(C24="","",IF(AND(OR(L24="1-Urgent",L24="2-High"),M24="✓"),"DO FIRST",IF(M24="✓","SCHEDULE",IF(OR(L24="1-Urgent",L24="2-High"),"DELEGATE","DELETE"))))
B25: 20 | C25: Schedule team meeting | D25: Business | E25: 46309 | F25: =IF(OR(C25="",E25=""),"",E25-Setup!$D$7) | G25: 0.39583333 | H25: 0.4375 | I25: =IF(OR(G25="",H25=""),"",TRIM(IF(HOUR(H25-G25)>0,HOUR(H25-G25)&" hr ","")&IF(MINUTE(H25-G25)>0,MINUTE(H25-G25)&" min",""))) | J25: In Progress | K25: 0.6 | L25: 3-Medium | M25: ✓ | N25: Rebecca | O25: =IF(C25="","",IF(AND(OR(L25="1-Urgent",L25="2-High"),M25="✓"),"DO FIRST",IF(M25="✓","SCHEDULE",IF(OR(L25="1-Urgent",L25="2-High"),"DELEGATE","DELETE"))))
B26: 21 | C26: Plan marketing campaign | D26: Business | E26: 46311 | F26: =IF(OR(C26="",E26=""),"",E26-Setup!$D$7) | I26: =IF(OR(G26="",H26=""),"",TRIM(IF(HOUR(H26-G26)>0,HOUR(H26-G26)&" hr ","")&IF(MINUTE(H26-G26)>0,MINUTE(H26-G26)&" min",""))) | J26: Not Started | L26: 3-Medium | N26: Lucy | O26: =IF(C26="","",IF(AND(OR(L26="1-Urgent",L26="2-High"),M26="✓"),"DO FIRST",IF(M26="✓","SCHEDULE",IF(OR(L26="1-Urgent",L26="2-High"),"DELEGATE","DELETE"))))
B27: 22 | C27: Review ad performance | D27: Business | E27: 46312 | F27: =IF(OR(C27="",E27=""),"",E27-Setup!$D$7) | G27: 0.64583333 | H27: 0.6875 | I27: =IF(OR(G27="",H27=""),"",TRIM(IF(HOUR(H27-G27)>0,HOUR(H27-G27)&" hr ","")&IF(MINUTE(H27-G27)>0,MINUTE(H27-G27)&" min",""))) | J27: In Progress | K27: 0.4 | L27: 4-Low | N27: Me | O27: =IF(C27="","",IF(AND(OR(L27="1-Urgent",L27="2-High"),M27="✓"),"DO FIRST",IF(M27="✓","SCHEDULE",IF(OR(L27="1-Urgent",L27="2-High"),"DELEGATE","DELETE"))))
B28: 23 | C28: Presentation Project X | D28: Business | E28: 46313 | F28: =IF(OR(C28="",E28=""),"",E28-Setup!$D$7) | I28: =IF(OR(G28="",H28=""),"",TRIM(IF(HOUR(H28-G28)>0,HOUR(H28-G28)&" hr ","")&IF(MINUTE(H28-G28)>0,MINUTE(H28-G28)&" min",""))) | L28: 3-Medium | N28: Lucy | O28: =IF(C28="","",IF(AND(OR(L28="1-Urgent",L28="2-High"),M28="✓"),"DO FIRST",IF(M28="✓","SCHEDULE",IF(OR(L28="1-Urgent",L28="2-High"),"DELEGATE","DELETE"))))
B29: 24 | C29: Mole Check | D29: Health | E29: 46314 | F29: =IF(OR(C29="",E29=""),"",E29-Setup!$D$7) | G29: 0.45833333 | H29: 0.48958333 | I29: =IF(OR(G29="",H29=""),"",TRIM(IF(HOUR(H29-G29)>0,HOUR(H29-G29)&" hr ","")&IF(MINUTE(H29-G29)>0,MINUTE(H29-G29)&" min",""))) | J29: In Progress | K29: 0.4 | L29: 4-Low | M29: ✓ | N29: Lucy | O29: =IF(C29="","",IF(AND(OR(L29="1-Urgent",L29="2-High"),M29="✓"),"DO FIRST",IF(M29="✓","SCHEDULE",IF(OR(L29="1-Urgent",L29="2-High"),"DELEGATE","DELETE"))))
B30: 25 | C30: Running | D30: Personal | E30: 46316 | F30: =IF(OR(C30="",E30=""),"",E30-Setup!$D$7) | G30: 0.66666667 | H30: 0.69791667 | I30: =IF(OR(G30="",H30=""),"",TRIM(IF(HOUR(H30-G30)>0,HOUR(H30-G30)&" hr ","")&IF(MINUTE(H30-G30)>0,MINUTE(H30-G30)&" min",""))) | L30: 3-Medium | N30: Sam | O30: =IF(C30="","",IF(AND(OR(L30="1-Urgent",L30="2-High"),M30="✓"),"DO FIRST",IF(M30="✓","SCHEDULE",IF(OR(L30="1-Urgent",L30="2-High"),"DELEGATE","DELETE"))))
B31: 26 | C31: Doctor Check Up | D31: Health | E31: 46317 | F31: =IF(OR(C31="",E31=""),"",E31-Setup!$D$7) | G31: 0.6875 | H31: 0.72916667 | I31: =IF(OR(G31="",H31=""),"",TRIM(IF(HOUR(H31-G31)>0,HOUR(H31-G31)&" hr ","")&IF(MINUTE(H31-G31)>0,MINUTE(H31-G31)&" min",""))) | J31: Not Started | L31: 2-High | M31: ✓ | N31: Tony | O31: =IF(C31="","",IF(AND(OR(L31="1-Urgent",L31="2-High"),M31="✓"),"DO FIRST",IF(M31="✓","SCHEDULE",IF(OR(L31="1-Urgent",L31="2-High"),"DELEGATE","DELETE"))))
B32: 27 | C32: Buy groceries | D32: Family | E32: 46318 | F32: =IF(OR(C32="",E32=""),"",E32-Setup!$D$7) | G32: 0.5625 | H32: 0.64583333 | I32: =IF(OR(G32="",H32=""),"",TRIM(IF(HOUR(H32-G32)>0,HOUR(H32-G32)&" hr ","")&IF(MINUTE(H32-G32)>0,MINUTE(H32-G32)&" min",""))) | J32: In Progress | K32: 0.8 | L32: 3-Medium | M32: ✓ | N32: Rebecca | O32: =IF(C32="","",IF(AND(OR(L32="1-Urgent",L32="2-High"),M32="✓"),"DO FIRST",IF(M32="✓","SCHEDULE",IF(OR(L32="1-Urgent",L32="2-High"),"DELEGATE","DELETE"))))
B33: 28 | C33: John's Birthday | D33: Birthdays | E33: 46320 | F33: =IF(OR(C33="",E33=""),"",E33-Setup!$D$7) | I33: =IF(OR(G33="",H33=""),"",TRIM(IF(HOUR(H33-G33)>0,HOUR(H33-G33)&" hr ","")&IF(MINUTE(H33-G33)>0,MINUTE(H33-G33)&" min",""))) | J33: Waiting | K33: 0.5 | L33: 2-High | M33: ✓ | N33: Me | O33: =IF(C33="","",IF(AND(OR(L33="1-Urgent",L33="2-High"),M33="✓"),"DO FIRST",IF(M33="✓","SCHEDULE",IF(OR(L33="1-Urgent",L33="2-High"),"DELEGATE","DELETE"))))
B34: 29 | C34: Test product features | D34: Business | E34: 46321 | F34: =IF(OR(C34="",E34=""),"",E34-Setup!$D$7) | G34: 0.6875 | H34: 0.72916667 | I34: =IF(OR(G34="",H34=""),"",TRIM(IF(HOUR(H34-G34)>0,HOUR(H34-G34)&" hr ","")&IF(MINUTE(H34-G34)>0,MINUTE(H34-G34)&" min",""))) | J34: Not Started | L34: 3-Medium | N34: Jamie | O34: =IF(C34="","",IF(AND(OR(L34="1-Urgent",L34="2-High"),M34="✓"),"DO FIRST",IF(M34="✓","SCHEDULE",IF(OR(L34="1-Urgent",L34="2-High"),"DELEGATE","DELETE"))))
B35: 30 | C35: Girls lunch | D35: Social | E35: 46322 | F35: =IF(OR(C35="",E35=""),"",E35-Setup!$D$7) | G35: 0.375 | H35: 0.44791667 | I35: =IF(OR(G35="",H35=""),"",TRIM(IF(HOUR(H35-G35)>0,HOUR(H35-G35)&" hr ","")&IF(MINUTE(H35-G35)>0,MINUTE(H35-G35)&" min",""))) | J35: Not Started | L35: 1-Urgent | M35: ✓ | N35: Lucy | O35: =IF(C35="","",IF(AND(OR(L35="1-Urgent",L35="2-High"),M35="✓"),"DO FIRST",IF(M35="✓","SCHEDULE",IF(OR(L35="1-Urgent",L35="2-High"),"DELEGATE","DELETE"))))
B36: 31 | C36: Facial Treatment | D36: Health | E36: 46324 | F36: =IF(OR(C36="",E36=""),"",E36-Setup!$D$7) | G36: 0.45833333 | H36: 0.48958333 | I36: =IF(OR(G36="",H36=""),"",TRIM(IF(HOUR(H36-G36)>0,HOUR(H36-G36)&" hr ","")&IF(MINUTE(H36-G36)>0,MINUTE(H36-G36)&" min",""))) | J36: Waiting | K36: 0.5 | L36: 2-High | N36: Tony | O36: =IF(C36="","",IF(AND(OR(L36="1-Urgent",L36="2-High"),M36="✓"),"DO FIRST",IF(M36="✓","SCHEDULE",IF(OR(L36="1-Urgent",L36="2-High"),"DELEGATE","DELETE"))))
B37: 32 | C37: Book massage | D37: Personal | E37: 46325 | F37: =IF(OR(C37="",E37=""),"",E37-Setup!$D$7) | G37: 0.375 | H37: 0.48958333 | I37: =IF(OR(G37="",H37=""),"",TRIM(IF(HOUR(H37-G37)>0,HOUR(H37-G37)&" hr ","")&IF(MINUTE(H37-G37)>0,MINUTE(H37-G37)&" min",""))) | J37: Not Started | L37: 3-Medium | M37: ✓ | N37: Tony | O37: =IF(C37="","",IF(AND(OR(L37="1-Urgent",L37="2-High"),M37="✓"),"DO FIRST",IF(M37="✓","SCHEDULE",IF(OR(L37="1-Urgent",L37="2-High"),"DELEGATE","DELETE"))))
B38: 33 | C38: Hair dresser | D38: Personal | E38: 46326 | F38: =IF(OR(C38="",E38=""),"",E38-Setup!$D$7) | G38: 0.6875 | H38: 0.6875 | I38: =IF(OR(G38="",H38=""),"",TRIM(IF(HOUR(H38-G38)>0,HOUR(H38-G38)&" hr ","")&IF(MINUTE(H38-G38)>0,MINUTE(H38-G38)&" min",""))) | J38: In Progress | K38: 0.4 | L38: 2-High | M38: ✓ | N38: Me | O38: =IF(C38="","",IF(AND(OR(L38="1-Urgent",L38="2-High"),M38="✓"),"DO FIRST",IF(M38="✓","SCHEDULE",IF(OR(L38="1-Urgent",L38="2-High"),"DELEGATE","DELETE"))))
B39: 34 | C39: Finalize budget allocation | D39: Business | E39: 46327 | F39: =IF(OR(C39="",E39=""),"",E39-Setup!$D$7) | G39: 0.375 | H39: 0.44791667 | I39: =IF(OR(G39="",H39=""),"",TRIM(IF(HOUR(H39-G39)>0,HOUR(H39-G39)&" hr ","")&IF(MINUTE(H39-G39)>0,MINUTE(H39-G39)&" min",""))) | J39: Not Started | L39: 4-Low | N39: Rebecca | O39: =IF(C39="","",IF(AND(OR(L39="1-Urgent",L39="2-High"),M39="✓"),"DO FIRST",IF(M39="✓","SCHEDULE",IF(OR(L39="1-Urgent",L39="2-High"),"DELEGATE","DELETE"))))
B40: 35 | C40: Call client | D40: Business | E40: 46329 | F40: =IF(OR(C40="",E40=""),"",E40-Setup!$D$7) | I40: =IF(OR(G40="",H40=""),"",TRIM(IF(HOUR(H40-G40)>0,HOUR(H40-G40)&" hr ","")&IF(MINUTE(H40-G40)>0,MINUTE(H40-G40)&" min",""))) | J40: In Progress | K40: 0.4 | L40: 3-Medium | N40: Rebecca | O40: =IF(C40="","",IF(AND(OR(L40="1-Urgent",L40="2-High"),M40="✓"),"DO FIRST",IF(M40="✓","SCHEDULE",IF(OR(L40="1-Urgent",L40="2-High"),"DELEGATE","DELETE"))))
B41: 36 | C41: Prepare launch checklist | D41: Business | E41: 46330 | F41: =IF(OR(C41="",E41=""),"",E41-Setup!$D$7) | I41: =IF(OR(G41="",H41=""),"",TRIM(IF(HOUR(H41-G41)>0,HOUR(H41-G41)&" hr ","")&IF(MINUTE(H41-G41)>0,MINUTE(H41-G41)&" min",""))) | J41: Waiting | K41: 0.5 | L41: 1-Urgent | M41: ✓ | N41: Sam | O41: =IF(C41="","",IF(AND(OR(L41="1-Urgent",L41="2-High"),M41="✓"),"DO FIRST",IF(M41="✓","SCHEDULE",IF(OR(L41="1-Urgent",L41="2-High"),"DELEGATE","DELETE"))))
...

Sheet Recurring Log
B2: RECURRING LOG
B3: Auto-generated from the Recurring Schedule — only update STATUS, PROGRESS & NOTES here.
B4: TASK DETAILS | E4: SCHEDULE | J4: STATUS & PROGRESS | L4: EISENHOWER MATRIX | P4: NOTES
B5: # | C5: TASK | D5: CATEGORY | E5: DUE DATE | F5: DAYS LEFT | G5: START | H5: END | I5: DURATION | J5: STATUS | K5: PROGRESS | L5: PRIORITY | M5: IMPORTANT | N5: DELEGATE TO | O5: DECISION | P5: NOTES
B6: =IF(R6="","",1) | C6: =IF(R6="","",IF(INDEX('Recurring Schedule'!$C$6:$C$45,R6)="","",INDEX('Recurring Schedule'!$C$6:$C$45,R6))) | D6: =IF(R6="","",IF(INDEX('Recurring Schedule'!$D$6:$D$45,R6)="","",INDEX('Recurring Schedule'!$D$6:$D$45,R6))) | E6: =IF(Q6="","",INDEX(Calc!$A$2:$A$367,Q6)) | F6: =IF(OR(C6="",E6=""),"",E6-Setup!$D$7) | G6: =IF(R6="","",IF(INDEX('Recurring Schedule'!$H$6:$H$45,R6)="","",INDEX('Recurring Schedule'!$H$6:$H$45,R6))) | H6: =IF(R6="","",IF(INDEX('Recurring Schedule'!$I$6:$I$45,R6)="","",INDEX('Recurring Schedule'!$I$6:$I$45,R6))) | I6: =IF(OR(G6="",H6=""),"",TRIM(IF(HOUR(H6-G6)>0,HOUR(H6-G6)&" hr ","")&IF(MINUTE(H6-G6)>0,MINUTE(H6-G6)&" min",""))) | L6: =IF(R6="","",IF(INDEX('Recurring Schedule'!$J$6:$J$45,R6)="","",INDEX('Recurring Schedule'!$J$6:$J$45,R6))) | M6: =IF(R6="","",IF(INDEX('Recurring Schedule'!$K$6:$K$45,R6)="","",INDEX('Recurring Schedule'!$K$6:$K$45,R6))) | N6: =IF(R6="","",IF(INDEX('Recurring Schedule'!$L$6:$L$45,R6)="","",INDEX('Recurring Schedule'!$L$6:$L$45,R6))) | O6: =IF(C6="","",IF(AND(OR(L6="1-Urgent",L6="2-High"),M6="✓"),"DO FIRST",IF(M6="✓","SCHEDULE",IF(OR(L6="1-Urgent",L6="2-High"),"DELEGATE","DELETE")))) | Q6: =IF(1>Calc!$AQ$368,"",MATCH(0,Calc!$AQ$2:$AQ$367,1)) | R6: =IF(Q6="","",SMALL(INDEX(Calc!$B$2:$AO$367,Q6,0),1-INDEX(Calc!$AQ$2:$AQ$367,Q6)))
B7: =IF(R7="","",2) | C7: =IF(R7="","",IF(INDEX('Recurring Schedule'!$C$6:$C$45,R7)="","",INDEX('Recurring Schedule'!$C$6:$C$45,R7))) | D7: =IF(R7="","",IF(INDEX('Recurring Schedule'!$D$6:$D$45,R7)="","",INDEX('Recurring Schedule'!$D$6:$D$45,R7))) | E7: =IF(Q7="","",INDEX(Calc!$A$2:$A$367,Q7)) | F7: =IF(OR(C7="",E7=""),"",E7-Setup!$D$7) | G7: =IF(R7="","",IF(INDEX('Recurring Schedule'!$H$6:$H$45,R7)="","",INDEX('Recurring Schedule'!$H$6:$H$45,R7))) | H7: =IF(R7="","",IF(INDEX('Recurring Schedule'!$I$6:$I$45,R7)="","",INDEX('Recurring Schedule'!$I$6:$I$45,R7))) | I7: =IF(OR(G7="",H7=""),"",TRIM(IF(HOUR(H7-G7)>0,HOUR(H7-G7)&" hr ","")&IF(MINUTE(H7-G7)>0,MINUTE(H7-G7)&" min",""))) | L7: =IF(R7="","",IF(INDEX('Recurring Schedule'!$J$6:$J$45,R7)="","",INDEX('Recurring Schedule'!$J$6:$J$45,R7))) | M7: =IF(R7="","",IF(INDEX('Recurring Schedule'!$K$6:$K$45,R7)="","",INDEX('Recurring Schedule'!$K$6:$K$45,R7))) | N7: =IF(R7="","",IF(INDEX('Recurring Schedule'!$L$6:$L$45,R7)="","",INDEX('Recurring Schedule'!$L$6:$L$45,R7))) | O7: =IF(C7="","",IF(AND(OR(L7="1-Urgent",L7="2-High"),M7="✓"),"DO FIRST",IF(M7="✓","SCHEDULE",IF(OR(L7="1-Urgent",L7="2-High"),"DELEGATE","DELETE")))) | Q7: =IF(2>Calc!$AQ$368,"",MATCH(1,Calc!$AQ$2:$AQ$367,1)) | R7: =IF(Q7="","",SMALL(INDEX(Calc!$B$2:$AO$367,Q7,0),2-INDEX(Calc!$AQ$2:$AQ$367,Q7)))
B8: =IF(R8="","",3) | C8: =IF(R8="","",IF(INDEX('Recurring Schedule'!$C$6:$C$45,R8)="","",INDEX('Recurring Schedule'!$C$6:$C$45,R8))) | D8: =IF(R8="","",IF(INDEX('Recurring Schedule'!$D$6:$D$45,R8)="","",INDEX('Recurring Schedule'!$D$6:$D$45,R8))) | E8: =IF(Q8="","",INDEX(Calc!$A$2:$A$367,Q8)) | F8: =IF(OR(C8="",E8=""),"",E8-Setup!$D$7) | G8: =IF(R8="","",IF(INDEX('Recurring Schedule'!$H$6:$H$45,R8)="","",INDEX('Recurring Schedule'!$H$6:$H$45,R8))) | H8: =IF(R8="","",IF(INDEX('Recurring Schedule'!$I$6:$I$45,R8)="","",INDEX('Recurring Schedule'!$I$6:$I$45,R8))) | I8: =IF(OR(G8="",H8=""),"",TRIM(IF(HOUR(H8-G8)>0,HOUR(H8-G8)&" hr ","")&IF(MINUTE(H8-G8)>0,MINUTE(H8-G8)&" min",""))) | L8: =IF(R8="","",IF(INDEX('Recurring Schedule'!$J$6:$J$45,R8)="","",INDEX('Recurring Schedule'!$J$6:$J$45,R8))) | M8: =IF(R8="","",IF(INDEX('Recurring Schedule'!$K$6:$K$45,R8)="","",INDEX('Recurring Schedule'!$K$6:$K$45,R8))) | N8: =IF(R8="","",IF(INDEX('Recurring Schedule'!$L$6:$L$45,R8)="","",INDEX('Recurring Schedule'!$L$6:$L$45,R8))) | O8: =IF(C8="","",IF(AND(OR(L8="1-Urgent",L8="2-High"),M8="✓"),"DO FIRST",IF(M8="✓","SCHEDULE",IF(OR(L8="1-Urgent",L8="2-High"),"DELEGATE","DELETE")))) | Q8: =IF(3>Calc!$AQ$368,"",MATCH(2,Calc!$AQ$2:$AQ$367,1)) | R8: =IF(Q8="","",SMALL(INDEX(Calc!$B$2:$AO$367,Q8,0),3-INDEX(Calc!$AQ$2:$AQ$367,Q8)))
