Workbook
Name PayCat: Payments!$I$6:$I$1205
Name PayAct: Payments!$Q$6:$Q$1205

Sheet Instructions
B2: ULTIMATE BUDGET PLANNER
C3: Annual · Monthly · Paycheck / any period — dark edition
C5: SETUP
C6: Enter your budget start date, opening balance, accounts, variable-expense budgets and every recurring income, bill, debt payment, subscription and savings transfer ONCE (sample data included — overwrite or delete it). Yellow cells are inputs everywhere.
C8: PAYMENTS
C9: Every recurring item auto-repeats here for 12 months, sorted by date and coloured by category. Mark ✓ paid / ✗ skipped (or leave 'Auto-mark paid' = Yes on Setup). Enter one-off changes in the VARIATION columns (new date, amount or account). Use the filter arrows to sort / filter.
C11: MANUAL LOG
C12: Log variable spending, irregular income, extra bills and transfers between accounts. Tip: sub-categories must match the names in Setup to land in the right table.
C14: ACCOUNTS
C15: Live balance of each account and your net worth.
C17: DASHBOARD
C18: Switch between Weekly / Bi-weekly / 4-weekly (paycheck) / Monthly / Quarterly / 6-month / Annual / Custom and pick a start date — the whole dashboard recalculates for that period.
C20: JAN – DEC
... C36: Built for Microsoft Excel 365 / 2021+. Don't type over white/black formula cells. If you edit recurring items after marking payments, re-check the ✓ marks (rows re-sort by date).

Sheet Setup
B2: BUDGET SETUP
B3: Yellow cells are inputs. Fill this sheet once — Payments, Calendar, every monthly tab and the dashboards update automatically.
C4: GENERAL | F4: ACCOUNTS | I4: VARIABLE EXPENSES
C5: Budget start date | D5: 46023 | F5: Account | G5: Opening bal. | I5: Category | J5: Monthly budget
C6: Opening balance | D6: 2500 | F6: Checking 1 | G6: 1500 | I6: Groceries | J6: 600
C7: Auto-mark paid | D7: Yes | F7: Checking 2 | G7: 1000 | I7: Eating Out | J7: 400
F8: Savings 1 | G8: 3000 | I8: Shopping | J8: 300
C9: Year end | D9: =EDATE(D5,12)-1 | F9: Savings 2 | G9: 500 | I9: Entertainment | J9: 150
C10: Auto-mark paid = Yes counts a scheduled item as paid once its date has passed (mark ✗ in Payments to skip one). | F10: Credit Card 1 | G10: -450 | I10: Transportation | J10: 250
C11: Opening balance = cash available at the start of month 1. | F11: Credit Card 2 | G11: -800 | I11: School | J11: 200
F12: Credit Card 3 | G12: -300 | I12: Pets | J12: 80
F13: Car Loan 1 | G13: -8000 | I13: Hair/Beauty | J13: 60
F14: Capital One | G14: -2400 | I14: Gifts | J14: 100
I15: Other | J15: 100
B23: RECURRING TRANSACTIONS — set up once, auto-repeats into Payments, Calendar & all tabs
B24: # | C24: Category | D24: Sub-category | E24: Amount | F24: Frequency | G24: Start date | H24: End date (opt.) | I24: From account | J24: To account | K24: Notes | L24: key | M24: days | N24: mths | O24: n0 | P24: end
B25: 1 | C25: Income | D25: Sam's Salary | E25: 1600 | F25: Bi-weekly | G25: 46024 | I25: N/A | J25: Checking 1 | L25: =IF(C25="","",C25&"|"&COUNTIF($C$25:C25,C25)) | M25: =IFERROR(VLOOKUP(F25,Lists!$C$2:$E$10,2,0),0) | N25: =IFERROR(VLOOKUP(F25,Lists!$C$2:$E$10,3,0),0) | O25: =IF(OR(G25="",F25="",F25="Once"),0,IF(M25>0,MAX(0,ROUNDUP(($D$5-G25)/M25,0)),IF(N25=0,0,MAX(0,ROUNDUP(((YEAR($D$5)-YEAR(G25))*12+MONTH($D$5)-MONTH(G25))/N25,0))+IF(EDATE(G25,MAX(0,ROUNDUP(((YEAR($D$5)-YEAR(G25))*12+MONTH($D$5)-MONTH(G25))/N25,0))*N25)<$D$5,1,0)))) | P25: =IF(H25="",$D$9,MIN(H25,$D$9))
B26: 2 | C26: Income | D26: Lisa's Salary | E26: 3200 | F26: Monthly | G26: 46036 | I26: N/A | J26: Checking 2 | L26: =IF(C26="","",C26&"|"&COUNTIF($C$25:C26,C26)) | M26: =IFERROR(VLOOKUP(F26,Lists!$C$2:$E$10,2,0),0) | N26: =IFERROR(VLOOKUP(F26,Lists!$C$2:$E$10,3,0),0) | O26: =IF(OR(G26="",F26="",F26="Once"),0,IF(M26>0,MAX(0,ROUNDUP(($D$5-G26)/M26,0)),IF(N26=0,0,MAX(0,ROUNDUP(((YEAR($D$5)-YEAR(G26))*12+MONTH($D$5)-MONTH(G26))/N26,0))+IF(EDATE(G26,MAX(0,ROUNDUP(((YEAR($D$5)-YEAR(G26))*12+MONTH($D$5)-MONTH(G26))/N26,0))*N26)<$D$5,1,0)))) | P26: =IF(H26="",$D$9,MIN(H26,$D$9))
B27: 3 | C27: Income | D27: Side Hustle | E27: 450 | F27: Monthly | G27: 46028 | I27: N/A | J27: Checking 1 | L27: =IF(C27="","",C27&"|"&COUNTIF($C$25:C27,C27)) | M27: =IFERROR(VLOOKUP(F27,Lists!$C$2:$E$10,2,0),0) | N27: =IFERROR(VLOOKUP(F27,Lists!$C$2:$E$10,3,0),0) | O27: =IF(OR(G27="",F27="",F27="Once"),0,IF(M27>0,MAX(0,ROUNDUP(($D$5-G27)/M27,0)),IF(N27=0,0,MAX(0,ROUNDUP(((YEAR($D$5)-YEAR(G27))*12+MONTH($D$5)-MONTH(G27))/N27,0))+IF(EDATE(G27,MAX(0,ROUNDUP(((YEAR($D$5)-YEAR(G27))*12+MONTH($D$5)-MONTH(G27))/N27,0))*N27)<$D$5,1,0)))) | P27: =IF(H27="",$D$9,MIN(H27,$D$9))
B28: 4 | C28: Bills | D28: Rent | E28: 1600 | F28: Monthly | G28: 46023 | I28: Checking 1 | J28: N/A | L28: =IF(C28="","",C28&"|"&COUNTIF($C$25:C28,C28)) | M28: =IFERROR(VLOOKUP(F28,Lists!$C$2:$E$10,2,0),0) | N28: =IFERROR(VLOOKUP(F28,Lists!$C$2:$E$10,3,0),0) | O28: =IF(OR(G28="",F28="",F28="Once"),0,IF(M28>0,MAX(0,ROUNDUP(($D$5-G28)/M28,0)),IF(N28=0,0,MAX(0,ROUNDUP(((YEAR($D$5)-YEAR(G28))*12+MONTH($D$5)-MONTH(G28))/N28,0))+IF(EDATE(G28,MAX(0,ROUNDUP(((YEAR($D$5)-YEAR(G28))*12+MONTH($D$5)-MONTH(G28))/N28,0))*N28)<$D$5,1,0)))) | P28: =IF(H28="",$D$9,MIN(H28,$D$9))
B29: 5 | C29: Bills | D29: Electricity Bill | E29: 140 | F29: Monthly | G29: 46024 | I29: Credit Card 1 | J29: N/A | L29: =IF(C29="","",C29&"|"&COUNTIF($C$25:C29,C29)) | M29: =IFERROR(VLOOKUP(F29,Lists!$C$2:$E$10,2,0),0) | N29: =IFERROR(VLOOKUP(F29,Lists!$C$2:$E$10,3,0),0) | O29: =IF(OR(G29="",F29="",F29="Once"),0,IF(M29>0,MAX(0,ROUNDUP(($D$5-G29)/M29,0)),IF(N29=0,0,MAX(0,ROUNDUP(((YEAR($D$5)-YEAR(G29))*12+MONTH($D$5)-MONTH(G29))/N29,0))+IF(EDATE(G29,MAX(0,ROUNDUP(((YEAR($D$5)-YEAR(G29))*12+MONTH($D$5)-MONTH(G29))/N29,0))*N29)<$D$5,1,0)))) | P29: =IF(H29="",$D$9,MIN(H29,$D$9))
B30: 6 | C30: Bills | D30: Gas Bill | E30: 50 | F30: Monthly | G30: 46024 | I30: Credit Card 1 | J30: N/A | L30: =IF(C30="","",C30&"|"&COUNTIF($C$25:C30,C30)) | M30: =IFERROR(VLOOKUP(F30,Lists!$C$2:$E$10,2,0),0) | N30: =IFERROR(VLOOKUP(F30,Lists!$C$2:$E$10,3,0),0) | O30: =IF(OR(G30="",F30="",F30="Once"),0,IF(M30>0,MAX(0,ROUNDUP(($D$5-G30)/M30,0)),IF(N30=0,0,MAX(0,ROUNDUP(((YEAR($D$5)-YEAR(G30))*12+MONTH($D$5)-MONTH(G30))/N30,0))+IF(EDATE(G30,MAX(0,ROUNDUP(((YEAR($D$5)-YEAR(G30))*12+MONTH($D$5)-MONTH(G30))/N30,0))*N30)<$D$5,1,0)))) | P30: =IF(H30="",$D$9,MIN(H30,$D$9))
B31: 7 | C31: Bills | D31: Water Bill | E31: 60 | F31: Monthly | G31: 46025 | I31: Credit Card 3 | J31: N/A | L31: =IF(C31="","",C31&"|"&COUNTIF($C$25:C31,C31)) | M31: =IFERROR(VLOOKUP(F31,Lists!$C$2:$E$10,2,0),0) | N31: =IFERROR(VLOOKUP(F31,Lists!$C$2:$E$10,3,0),0) | O31: =IF(OR(G31="",F31="",F31="Once"),0,IF(M31>0,MAX(0,ROUNDUP(($D$5-G31)/M31,0)),IF(N31=0,0,MAX(0,ROUNDUP(((YEAR($D$5)-YEAR(G31))*12+MONTH($D$5)-MONTH(G31))/N31,0))+IF(EDATE(G31,MAX(0,ROUNDUP(((YEAR($D$5)-YEAR(G31))*12+MONTH($D$5)-MONTH(G31))/N31,0))*N31)<$D$5,1,0)))) | P31: =IF(H31="",$D$9,MIN(H31,$D$9))
B32: 8 | C32: Bills | D32: Internet | E32: 75 | F32: Monthly | G32: 46031 | I32: Credit Card 2 | J32: N/A | L32: =IF(C32="","",C32&"|"&COUNTIF($C$25:C32,C32)) | M32: =IFERROR(VLOOKUP(F32,Lists!$C$2:$E$10,2,0),0) | N32: =IFERROR(VLOOKUP(F32,Lists!$C$2:$E$10,3,0),0) | O32: =IF(OR(G32="",F32="",F32="Once"),0,IF(M32>0,MAX(0,ROUNDUP(($D$5-G32)/M32,0)),IF(N32=0,0,MAX(0,ROUNDUP(((YEAR($D$5)-YEAR(G32))*12+MONTH($D$5)-MONTH(G32))/N32,0))+IF(EDATE(G32,MAX(0,ROUNDUP(((YEAR($D$5)-YEAR(G32))*12+MONTH($D$5)-MONTH(G32))/N32,0))*N32)<$D$5,1,0)))) | P32: =IF(H32="",$D$9,MIN(H32,$D$9))
B33: 9 | C33: Bills | D33: Phone Bill | E33: 75 | F33: Monthly | G33: 46031 | I33: Credit Card 1 | J33: N/A | L33: =IF(C33="","",C33&"|"&COUNTIF($C$25:C33,C33)) | M33: =IFERROR(VLOOKUP(F33,Lists!$C$2:$E$10,2,0),0) | N33: =IFERROR(VLOOKUP(F33,Lists!$C$2:$E$10,3,0),0) | O33: =IF(OR(G33="",F33="",F33="Once"),0,IF(M33>0,MAX(0,ROUNDUP(($D$5-G33)/M33,0)),IF(N33=0,0,MAX(0,ROUNDUP(((YEAR($D$5)-YEAR(G33))*12+MONTH($D$5)-MONTH(G33))/N33,0))+IF(EDATE(G33,MAX(0,ROUNDUP(((YEAR($D$5)-YEAR(G33))*12+MONTH($D$5)-MONTH(G33))/N33,0))*N33)<$D$5,1,0)))) | P33: =IF(H33="",$D$9,MIN(H33,$D$9))
B34: 10 | C34: Bills | D34: Health Insurance | E34: 150 | F34: Monthly | G34: 46024 | I34: Credit Card 2 | J34: N/A | L34: =IF(C34="","",C34&"|"&COUNTIF($C$25:C34,C34)) | M34: =IFERROR(VLOOKUP(F34,Lists!$C$2:$E$10,2,0),0) | N34: =IFERROR(VLOOKUP(F34,Lists!$C$2:$E$10,3,0),0) | O34: =IF(OR(G34="",F34="",F34="Once"),0,IF(M34>0,MAX(0,ROUNDUP(($D$5-G34)/M34,0)),IF(N34=0,0,MAX(0,ROUNDUP(((YEAR($D$5)-YEAR(G34))*12+MONTH($D$5)-MONTH(G34))/N34,0))+IF(EDATE(G34,MAX(0,ROUNDUP(((YEAR($D$5)-YEAR(G34))*12+MONTH($D$5)-MONTH(G34))/N34,0))*N34)<$D$5,1,0)))) | P34: =IF(H34="",$D$9,MIN(H34,$D$9))
B35: 11 | C35: Bills | D35: Car Insurance | E35: 60 | F35: Monthly | G35: 46028 | I35: Credit Card 2 | J35: N/A | L35: =IF(C35="","",C35&"|"&COUNTIF($C$25:C35,C35)) | M35: =IFERROR(VLOOKUP(F35,Lists!$C$2:$E$10,2,0),0) | N35: =IFERROR(VLOOKUP(F35,Lists!$C$2:$E$10,3,0),0) | O35: =IF(OR(G35="",F35="",F35="Once"),0,IF(M35>0,MAX(0,ROUNDUP(($D$5-G35)/M35,0)),IF(N35=0,0,MAX(0,ROUNDUP(((YEAR($D$5)-YEAR(G35))*12+MONTH($D$5)-MONTH(G35))/N35,0))+IF(EDATE(G35,MAX(0,ROUNDUP(((YEAR($D$5)-YEAR(G35))*12+MONTH($D$5)-MONTH(G35))/N35,0))*N35)<$D$5,1,0)))) | P35: =IF(H35="",$D$9,MIN(H35,$D$9))
B36: 12 | C36: Bills | D36: Home Insurance | E36: 55 | F36: Monthly | G36: 46033 | I36: Credit Card 2 | J36: N/A | L36: =IF(C36="","",C36&"|"&COUNTIF($C$25:C36,C36)) | M36: =IFERROR(VLOOKUP(F36,Lists!$C$2:$E$10,2,0),0) | N36: =IFERROR(VLOOKUP(F36,Lists!$C$2:$E$10,3,0),0) | O36: =IF(OR(G36="",F36="",F36="Once"),0,IF(M36>0,MAX(0,ROUNDUP(($D$5-G36)/M36,0)),IF(N36=0,0,MAX(0,ROUNDUP(((YEAR($D$5)-YEAR(G36))*12+MONTH($D$5)-MONTH(G36))/N36,0))+IF(EDATE(G36,MAX(0,ROUNDUP(((YEAR($D$5)-YEAR(G36))*12+MONTH($D$5)-MONTH(G36))/N36,0))*N36)<$D$5,1,0)))) | P36: =IF(H36="",$D$9,MIN(H36,$D$9))
... B53: 29 | C53: Savings | D53: Emergency Fund | E53: 300 | F53: Monthly | G53: 46037 | I53: Checking 2 | J53: Savings 1 | L53: =IF(C53="","",C53&"|"&COUNTIF($C$25:C53,C53)) | M53: =IFERROR(VLOOKUP(F53,Lists!$C$2:$E$10,2,0),0) | N53: =IFERROR(VLOOKUP(F53,Lists!$C$2:$E$10,3,0),0) | O53: =IF(OR(G53="",F53="",F53="Once"),0,IF(M53>0,MAX(0,ROUNDUP(($D$5-G53)/M53,0)),IF(N53=0,0,MAX(0,ROUNDUP(((YEAR($D$5)-YEAR(G53))*12+MONTH($D$5)-MONTH(G53))/N53,0))+IF(EDATE(G53,MAX(0,ROUNDUP(((YEAR($D$5)-YEAR(G53))*12+MONTH($D$5)-MONTH(G53))/N53,0))*N53)<$D$5,1,0)))) | P53: =IF(H53="",$D$9,MIN(H53,$D$9))
B54: 30 | C54: Savings | D54: New Laptop | E54: 150 | F54: Monthly | G54: 46037 | H54: 46326 | I54: Checking 2 | J54: Savings 2 | L54: =IF(C54="","",C54&"|"&COUNTIF($C$25:C54,C54)) | M54: =IFERROR(VLOOKUP(F54,Lists!$C$2:$E$10,2,0),0) | N54: =IFERROR(VLOOKUP(F54,Lists!$C$2:$E$10,3,0),0) | O54: =IF(OR(G54="",F54="",F54="Once"),0,IF(M54>0,MAX(0,ROUNDUP(($D$5-G54)/M54,0)),IF(N54=0,0,MAX(0,ROUNDUP(((YEAR($D$5)-YEAR(G54))*12+MONTH($D$5)-MONTH(G54))/N54,0))+IF(EDATE(G54,MAX(0,ROUNDUP(((YEAR($D$5)-YEAR(G54))*12+MONTH($D$5)-MONTH(G54))/N54,0))*N54)<$D$5,1,0)))) | P54: =IF(H54="",$D$9,MIN(H54,$D$9))
B55: 31 | C55: Savings | D55: Home Repairs | E55: 150 | F55: Monthly | G55: 46042 | I55: Checking 2 | J55: Savings 1 | L55: =IF(C55="","",C55&"|"&COUNTIF($C$25:C55,C55)) | M55: =IFERROR(VLOOKUP(F55,Lists!$C$2:$E$10,2,0),0) | N55: =IFERROR(VLOOKUP(F55,Lists!$C$2:$E$10,3,0),0) | O55: =IF(OR(G55="",F55="",F55="Once"),0,IF(M55>0,MAX(0,ROUNDUP(($D$5-G55)/M55,0)),IF(N55=0,0,MAX(0,ROUNDUP(((YEAR($D$5)-YEAR(G55))*12+MONTH($D$5)-MONTH(G55))/N55,0))+IF(EDATE(G55,MAX(0,ROUNDUP(((YEAR($D$5)-YEAR(G55))*12+MONTH($D$5)-MONTH(G55))/N55,0))*N55)<$D$5,1,0)))) | P55: =IF(H55="",$D$9,MIN(H55,$D$9))
B56: 32 | C56: Savings | D56: Wedding | E56: 200 | F56: Monthly | G56: 46028 | I56: Checking 1 | J56: Savings 2 | L56: =IF(C56="","",C56&"|"&COUNTIF($C$25:C56,C56)) | M56: =IFERROR(VLOOKUP(F56,Lists!$C$2:$E$10,2,0),0) | N56: =IFERROR(VLOOKUP(F56,Lists!$C$2:$E$10,3,0),0) | O56: =IF(OR(G56="",F56="",F56="Once"),0,IF(M56>0,MAX(0,ROUNDUP(($D$5-G56)/M56,0)),IF(N56=0,0,MAX(0,ROUNDUP(((YEAR($D$5)-YEAR(G56))*12+MONTH($D$5)-MONTH(G56))/N56,0))+IF(EDATE(G56,MAX(0,ROUNDUP(((YEAR($D$5)-YEAR(G56))*12+MONTH($D$5)-MONTH(G56))/N56,0))*N56)<$D$5,1,0)))) | P56: =IF(H56="",$D$9,MIN(H56,$D$9))
B57: 33 | L57: =IF(C57="","",C57&"|"&COUNTIF($C$25:C57,C57)) | M57: =IFERROR(VLOOKUP(F57,Lists!$C$2:$E$10,2,0),0) | N57: =IFERROR(VLOOKUP(F57,Lists!$C$2:$E$10,3,0),0) | O57: =IF(OR(G57="",F57="",F57="Once"),0,IF(M57>0,MAX(0,ROUNDUP(($D$5-G57)/M57,0)),IF(N57=0,0,MAX(0,ROUNDUP(((YEAR($D$5)-YEAR(G57))*12+MONTH($D$5)-MONTH(G57))/N57,0))+IF(EDATE(G57,MAX(0,ROUNDUP(((YEAR($D$5)-YEAR(G57))*12+MONTH($D$5)-MONTH(G57))/N57,0))*N57)<$D$5,1,0)))) | P57: =IF(H57="",$D$9,MIN(H57,$D$9))
B58: 34 | L58: =IF(C58="","",C58&"|"&COUNTIF($C$25:C58,C58)) | M58: =IFERROR(VLOOKUP(F58,Lists!$C$2:$E$10,2,0),0) | N58: =IFERROR(VLOOKUP(F58,Lists!$C$2:$E$10,3,0),0) | O58: =IF(OR(G58="",F58="",F58="Once"),0,IF(M58>0,MAX(0,ROUNDUP(($D$5-G58)/M58,0)),IF(N58=0,0,MAX(0,ROUNDUP(((YEAR($D$5)-YEAR(G58))*12+MONTH($D$5)-MONTH(G58))/N58,0))+IF(EDATE(G58,MAX(0,ROUNDUP(((YEAR($D$5)-YEAR(G58))*12+MONTH($D$5)-MONTH(G58))/N58,0))*N58)<$D$5,1,0)))) | P58: =IF(H58="",$D$9,MIN(H58,$D$9))
B59: 35 | L59: =IF(C59="","",C59&"|"&COUNTIF($C$25:C59,C59)) | M59: =IFERROR(VLOOKUP(F59,Lists!$C$2:$E$10,2,0),0) | N59: =IFERROR(VLOOKUP(F59,Lists!$C$2:$E$10,3,0),0) | O59: =IF(OR(G59="",F59="",F59="Once"),0,IF(M59>0,MAX(0,ROUNDUP(($D$5-G59)/M59,0)),IF(N59=0,0,MAX(0,ROUNDUP(((YEAR($D$5)-YEAR(G59))*12+MONTH($D$5)-MONTH(G59))/N59,0))+IF(EDATE(G59,MAX(0,ROUNDUP(((YEAR($D$5)-YEAR(G59))*12+MONTH($D$5)-MONTH(G59))/N59,0))*N59)<$D$5,1,0)))) | P59: =IF(H59="",$D$9,MIN(H59,$D$9))
B60: 36 | L60: =IF(C60="","",C60&"|"&COUNTIF($C$25:C60,C60)) | M60: =IFERROR(VLOOKUP(F60,Lists!$C$2:$E$10,2,0),0) | N60: =IFERROR(VLOOKUP(F60,Lists!$C$2:$E$10,3,0),0) | O60: =IF(OR(G60="",F60="",F60="Once"),0,IF(M60>0,MAX(0,ROUNDUP(($D$5-G60)/M60,0)),IF(N60=0,0,MAX(0,ROUNDUP(((YEAR($D$5)-YEAR(G60))*12+MONTH($D$5)-MONTH(G60))/N60,0))+IF(EDATE(G60,MAX(0,ROUNDUP(((YEAR($D$5)-YEAR(G60))*12+MONTH($D$5)-MONTH(G60))/N60,0))*N60)<$D$5,1,0)))) | P60: =IF(H60="",$D$9,MIN(H60,$D$9))
B61: 37 | L61: =IF(C61="","",C61&"|"&COUNTIF($C$25:C61,C61)) | M61: =IFERROR(VLOOKUP(F61,Lists!$C$2:$E$10,2,0),0) | N61: =IFERROR(VLOOKUP(F61,Lists!$C$2:$E$10,3,0),0) | O61: =IF(OR(G61="",F61="",F61="Once"),0,IF(M61>0,MAX(0,ROUNDUP(($D$5-G61)/M61,0)),IF(N61=0,0,MAX(0,ROUNDUP(((YEAR($D$5)-YEAR(G61))*12+MONTH($D$5)-MONTH(G61))/N61,0))+IF(EDATE(G61,MAX(0,ROUNDUP(((YEAR($D$5)-YEAR(G61))*12+MONTH($D$5)-MONTH(G61))/N61,0))*N61)<$D$5,1,0)))) | P61: =IF(H61="",$D$9,MIN(H61,$D$9))
B62: 38 | L62: =IF(C62="","",C62&"|"&COUNTIF($C$25:C62,C62)) | M62: =IFERROR(VLOOKUP(F62,Lists!$C$2:$E$10,2,0),0) | N62: =IFERROR(VLOOKUP(F62,Lists!$C$2:$E$10,3,0),0) | O62: =IF(OR(G62="",F62="",F62="Once"),0,IF(M62>0,MAX(0,ROUNDUP(($D$5-G62)/M62,0)),IF(N62=0,0,MAX(0,ROUNDUP(((YEAR($D$5)-YEAR(G62))*12+MONTH($D$5)-MONTH(G62))/N62,0))+IF(EDATE(G62,MAX(0,ROUNDUP(((YEAR($D$5)-YEAR(G62))*12+MONTH($D$5)-MONTH(G62))/N62,0))*N62)<$D$5,1,0)))) | P62: =IF(H62="",$D$9,MIN(H62,$D$9))
B63: 39 | L63: =IF(C63="","",C63&"|"&COUNTIF($C$25:C63,C63)) | M63: =IFERROR(VLOOKUP(F63,Lists!$C$2:$E$10,2,0),0) | N63: =IFERROR(VLOOKUP(F63,Lists!$C$2:$E$10,3,0),0) | O63: =IF(OR(G63="",F63="",F63="Once"),0,IF(M63>0,MAX(0,ROUNDUP(($D$5-G63)/M63,0)),IF(N63=0,0,MAX(0,ROUNDUP(((YEAR($D$5)-YEAR(G63))*12+MONTH($D$5)-MONTH(G63))/N63,0))+IF(EDATE(G63,MAX(0,ROUNDUP(((YEAR($D$5)-YEAR(G63))*12+MONTH($D$5)-MONTH(G63))/N63,0))*N63)<$D$5,1,0)))) | P63: =IF(H63="",$D$9,MIN(H63,$D$9))
B64: 40 | L64: =IF(C64="","",C64&"|"&COUNTIF($C$25:C64,C64)) | M64: =IFERROR(VLOOKUP(F64,Lists!$C$2:$E$10,2,0),0) | N64: =IFERROR(VLOOKUP(F64,Lists!$C$2:$E$10,3,0),0) | O64: =IF(OR(G64="",F64="",F64="Once"),0,IF(M64>0,MAX(0,ROUNDUP(($D$5-G64)/M64,0)),IF(N64=0,0,MAX(0,ROUNDUP(((YEAR($D$5)-YEAR(G64))*12+MONTH($D$5)-MONTH(G64))/N64,0))+IF(EDATE(G64,MAX(0,ROUNDUP(((YEAR($D$5)-YEAR(G64))*12+MONTH($D$5)-MONTH(G64))/N64,0))*N64)<$D$5,1,0)))) | P64: =IF(H64="",$D$9,MIN(H64,$D$9))
...

Sheet Payments
C2: PAYMENT SCHEDULE
C3: Auto-generated from Setup. Mark ✓ paid / ✗ skipped, use the filter arrows to sort & filter. Row colours follow the category.
C4: PAYMENT SCHEDULE | K4: VARIATION — enter any change for one payment here | P4: RESULT
A5: key | B5: idx | C5: PAID | D5: DATE | E5: SUB-CATEGORY | F5: AMOUNT | G5: FROM ACCOUNT | H5: TO ACCOUNT | I5: CATEGORY | K5: NEW DATE | L5: NEW AMOUNT | M5: NEW FROM | N5: NEW TO | P5: EFF. DATE | Q5: ACTUAL PAID | R5: EFF. FROM | S5: EFF. TO | T5: STATUS | U5: SCHEDULED
A6: =IFERROR(SMALL(Calc!$B$2:$BB$61,1),"") | B6: =IF(A6="","",ROUND(MOD(A6,1)*1000,0)) | D6: =IF(A6="","",INT(A6)) | E6: =IF(B6="","",INDEX(Setup!$D$25:$D$84,B6)) | F6: =IF(B6="","",INDEX(Setup!$E$25:$E$84,B6)) | G6: =IF(B6="","",INDEX(Setup!$I$25:$I$84,B6)&"") | H6: =IF(B6="","",INDEX(Setup!$J$25:$J$84,B6)&"") | I6: =IF(B6="","",INDEX(Setup!$C$25:$C$84,B6)) | P6: =IF(A6="","",IF(K6<>"",K6,D6)) | Q6: =IF(A6="",0,IF(C6="✗",0,IF(OR(C6="✓",AND(Setup!$D$7="Yes",P6<=TODAY())),IF(L6<>"",L6,F6),0))) | R6: =IF(A6="","",IF(M6<>"",M6,G6)) | S6: =IF(A6="","",IF(N6<>"",N6,H6)) | T6: =IF(A6="","",IF(C6="✗","Skipped",IF(Q6>0,"Paid","Upcoming"))) | U6: =IF(A6="",0,IF(C6="✗",0,IF(L6<>"",L6,F6)))
A7: =IFERROR(SMALL(Calc!$B$2:$BB$61,2),"") | B7: =IF(A7="","",ROUND(MOD(A7,1)*1000,0)) | D7: =IF(A7="","",INT(A7)) | E7: =IF(B7="","",INDEX(Setup!$D$25:$D$84,B7)) | F7: =IF(B7="","",INDEX(Setup!$E$25:$E$84,B7)) | G7: =IF(B7="","",INDEX(Setup!$I$25:$I$84,B7)&"") | H7: =IF(B7="","",INDEX(Setup!$J$25:$J$84,B7)&"") | I7: =IF(B7="","",INDEX(Setup!$C$25:$C$84,B7)) | P7: =IF(A7="","",IF(K7<>"",K7,D7)) | Q7: =IF(A7="",0,IF(C7="✗",0,IF(OR(C7="✓",AND(Setup!$D$7="Yes",P7<=TODAY())),IF(L7<>"",L7,F7),0))) | R7: =IF(A7="","",IF(M7<>"",M7,G7)) | S7: =IF(A7="","",IF(N7<>"",N7,H7)) | T7: =IF(A7="","",IF(C7="✗","Skipped",IF(Q7>0,"Paid","Upcoming"))) | U7: =IF(A7="",0,IF(C7="✗",0,IF(L7<>"",L7,F7)))
A8: =IFERROR(SMALL(Calc!$B$2:$BB$61,3),"") | B8: =IF(A8="","",ROUND(MOD(A8,1)*1000,0)) | D8: =IF(A8="","",INT(A8)) | E8: =IF(B8="","",INDEX(Setup!$D$25:$D$84,B8)) | F8: =IF(B8="","",INDEX(Setup!$E$25:$E$84,B8)) | G8: =IF(B8="","",INDEX(Setup!$I$25:$I$84,B8)&"") | H8: =IF(B8="","",INDEX(Setup!$J$25:$J$84,B8)&"") | I8: =IF(B8="","",INDEX(Setup!$C$25:$C$84,B8)) | P8: =IF(A8="","",IF(K8<>"",K8,D8)) | Q8: =IF(A8="",0,IF(C8="✗",0,IF(OR(C8="✓",AND(Setup!$D$7="Yes",P8<=TODAY())),IF(L8<>"",L8,F8),0))) | R8: =IF(A8="","",IF(M8<>"",M8,G8)) | S8: =IF(A8="","",IF(N8<>"",N8,H8)) | T8: =IF(A8="","",IF(C8="✗","Skipped",IF(Q8>0,"Paid","Upcoming"))) | U8: =IF(A8="",0,IF(C8="✗",0,IF(L8<>"",L8,F8)))
A9: =IFERROR(SMALL(Calc!$B$2:$BB$61,4),"") | B9: =IF(A9="","",ROUND(MOD(A9,1)*1000,0)) | D9: =IF(A9="","",INT(A9)) | E9: =IF(B9="","",INDEX(Setup!$D$25:$D$84,B9)) | F9: =IF(B9="","",INDEX(Setup!$E$25:$E$84,B9)) | G9: =IF(B9="","",INDEX(Setup!$I$25:$I$84,B9)&"") | H9: =IF(B9="","",INDEX(Setup!$J$25:$J$84,B9)&"") | I9: =IF(B9="","",INDEX(Setup!$C$25:$C$84,B9)) | P9: =IF(A9="","",IF(K9<>"",K9,D9)) | Q9: =IF(A9="",0,IF(C9="✗",0,IF(OR(C9="✓",AND(Setup!$D$7="Yes",P9<=TODAY())),IF(L9<>"",L9,F9),0))) | R9: =IF(A9="","",IF(M9<>"",M9,G9)) | S9: =IF(A9="","",IF(N9<>"",N9,H9)) | T9: =IF(A9="","",IF(C9="✗","Skipped",IF(Q9>0,"Paid","Upcoming"))) | U9: =IF(A9="",0,IF(C9="✗",0,IF(L9<>"",L9,F9)))
A10: =IFERROR(SMALL(Calc!$B$2:$BB$61,5),"") | B10: =IF(A10="","",ROUND(MOD(A10,1)*1000,0)) | D10: =IF(A10="","",INT(A10)) | E10: =IF(B10="","",INDEX(Setup!$D$25:$D$84,B10)) | F10: =IF(B10="","",INDEX(Setup!$E$25:$E$84,B10)) | G10: =IF(B10="","",INDEX(Setup!$I$25:$I$84,B10)&"") | H10: =IF(B10="","",INDEX(Setup!$J$25:$J$84,B10)&"") | I10: =IF(B10="","",INDEX(Setup!$C$25:$C$84,B10)) | P10: =IF(A10="","",IF(K10<>"",K10,D10)) | Q10: =IF(A10="",0,IF(C10="✗",0,IF(OR(C10="✓",AND(Setup!$D$7="Yes",P10<=TODAY())),IF(L10<>"",L10,F10),0))) | R10: =IF(A10="","",IF(M10<>"",M10,G10)) | S10: =IF(A10="","",IF(N10<>"",N10,H10)) | T10: =IF(A10="","",IF(C10="✗","Skipped",IF(Q10>0,"Paid","Upcoming"))) | U10: =IF(A10="",0,IF(C10="✗",0,IF(L10<>"",L10,F10)))
A11: =IFERROR(SMALL(Calc!$B$2:$BB$61,6),"") | B11: =IF(A11="","",ROUND(MOD(A11,1)*1000,0)) | D11: =IF(A11="","",INT(A11)) | E11: =IF(B11="","",INDEX(Setup!$D$25:$D$84,B11)) | F11: =IF(B11="","",INDEX(Setup!$E$25:$E$84,B11)) | G11: =IF(B11="","",INDEX(Setup!$I$25:$I$84,B11)&"") | H11: =IF(B11="","",INDEX(Setup!$J$25:$J$84,B11)&"") | I11: =IF(B11="","",INDEX(Setup!$C$25:$C$84,B11)) | P11: =IF(A11="","",IF(K11<>"",K11,D11)) | Q11: =IF(A11="",0,IF(C11="✗",0,IF(OR(C11="✓",AND(Setup!$D$7="Yes",P11<=TODAY())),IF(L11<>"",L11,F11),0))) | R11: =IF(A11="","",IF(M11<>"",M11,G11)) | S11: =IF(A11="","",IF(N11<>"",N11,H11)) | T11: =IF(A11="","",IF(C11="✗","Skipped",IF(Q11>0,"Paid","Upcoming"))) | U11: =IF(A11="",0,IF(C11="✗",0,IF(L11<>"",L11,F11)))
A12: =IFERROR(SMALL(Calc!$B$2:$BB$61,7),"") | B12: =IF(A12="","",ROUND(MOD(A12,1)*1000,0)) | D12: =IF(A12="","",INT(A12)) | E12: =IF(B12="","",INDEX(Setup!$D$25:$D$84,B12)) | F12: =IF(B12="","",INDEX(Setup!$E$25:$E$84,B12)) | G12: =IF(B12="","",INDEX(Setup!$I$25:$I$84,B12)&"") | H12: =IF(B12="","",INDEX(Setup!$J$25:$J$84,B12)&"") | I12: =IF(B12="","",INDEX(Setup!$C$25:$C$84,B12)) | P12: =IF(A12="","",IF(K12<>"",K12,D12)) | Q12: =IF(A12="",0,IF(C12="✗",0,IF(OR(C12="✓",AND(Setup!$D$7="Yes",P12<=TODAY())),IF(L12<>"",L12,F12),0))) | R12: =IF(A12="","",IF(M12<>"",M12,G12)) | S12: =IF(A12="","",IF(N12<>"",N12,H12)) | T12: =IF(A12="","",IF(C12="✗","Skipped",IF(Q12>0,"Paid","Upcoming"))) | U12: =IF(A12="",0,IF(C12="✗",0,IF(L12<>"",L12,F12)))
A13: =IFERROR(SMALL(Calc!$B$2:$BB$61,8),"") | B13: =IF(A13="","",ROUND(MOD(A13,1)*1000,0)) | D13: =IF(A13="","",INT(A13)) | E13: =IF(B13="","",INDEX(Setup!$D$25:$D$84,B13)) | F13: =IF(B13="","",INDEX(Setup!$E$25:$E$84,B13)) | G13: =IF(B13="","",INDEX(Setup!$I$25:$I$84,B13)&"") | H13: =IF(B13="","",INDEX(Setup!$J$25:$J$84,B13)&"") | I13: =IF(B13="","",INDEX(Setup!$C$25:$C$84,B13)) | P13: =IF(A13="","",IF(K13<>"",K13,D13)) | Q13: =IF(A13="",0,IF(C13="✗",0,IF(OR(C13="✓",AND(Setup!$D$7="Yes",P13<=TODAY())),IF(L13<>"",L13,F13),0))) | R13: =IF(A13="","",IF(M13<>"",M13,G13)) | S13: =IF(A13="","",IF(N13<>"",N13,H13)) | T13: =IF(A13="","",IF(C13="✗","Skipped",IF(Q13>0,"Paid","Upcoming"))) | U13: =IF(A13="",0,IF(C13="✗",0,IF(L13<>"",L13,F13)))
A14: =IFERROR(SMALL(Calc!$B$2:$BB$61,9),"") | B14: =IF(A14="","",ROUND(MOD(A14,1)*1000,0)) | D14: =IF(A14="","",INT(A14)) | E14: =IF(B14="","",INDEX(Setup!$D$25:$D$84,B14)) | F14: =IF(B14="","",INDEX(Setup!$E$25:$E$84,B14)) | G14: =IF(B14="","",INDEX(Setup!$I$25:$I$84,B14)&"") | H14: =IF(B14="","",INDEX(Setup!$J$25:$J$84,B14)&"") | I14: =IF(B14="","",INDEX(Setup!$C$25:$C$84,B14)) | P14: =IF(A14="","",IF(K14<>"",K14,D14)) | Q14: =IF(A14="",0,IF(C14="✗",0,IF(OR(C14="✓",AND(Setup!$D$7="Yes",P14<=TODAY())),IF(L14<>"",L14,F14),0))) | R14: =IF(A14="","",IF(M14<>"",M14,G14)) | S14: =IF(A14="","",IF(N14<>"",N14,H14)) | T14: =IF(A14="","",IF(C14="✗","Skipped",IF(Q14>0,"Paid","Upcoming"))) | U14: =IF(A14="",0,IF(C14="✗",0,IF(L14<>"",L14,F14)))
A15: =IFERROR(SMALL(Calc!$B$2:$BB$61,10),"") | B15: =IF(A15="","",ROUND(MOD(A15,1)*1000,0)) | D15: =IF(A15="","",INT(A15)) | E15: =IF(B15="","",INDEX(Setup!$D$25:$D$84,B15)) | F15: =IF(B15="","",INDEX(Setup!$E$25:$E$84,B15)) | G15: =IF(B15="","",INDEX(Setup!$I$25:$I$84,B15)&"") | H15: =IF(B15="","",INDEX(Setup!$J$25:$J$84,B15)&"") | I15: =IF(B15="","",INDEX(Setup!$C$25:$C$84,B15)) | P15: =IF(A15="","",IF(K15<>"",K15,D15)) | Q15: =IF(A15="",0,IF(C15="✗",0,IF(OR(C15="✓",AND(Setup!$D$7="Yes",P15<=TODAY())),IF(L15<>"",L15,F15),0))) | R15: =IF(A15="","",IF(M15<>"",M15,G15)) | S15: =IF(A15="","",IF(N15<>"",N15,H15)) | T15: =IF(A15="","",IF(C15="✗","Skipped",IF(Q15>0,"Paid","Upcoming"))) | U15: =IF(A15="",0,IF(C15="✗",0,IF(L15<>"",L15,F15)))
A16: =IFERROR(SMALL(Calc!$B$2:$BB$61,11),"") | B16: =IF(A16="","",ROUND(MOD(A16,1)*1000,0)) | D16: =IF(A16="","",INT(A16)) | E16: =IF(B16="","",INDEX(Setup!$D$25:$D$84,B16)) | F16: =IF(B16="","",INDEX(Setup!$E$25:$E$84,B16)) | G16: =IF(B16="","",INDEX(Setup!$I$25:$I$84,B16)&"") | H16: =IF(B16="","",INDEX(Setup!$J$25:$J$84,B16)&"") | I16: =IF(B16="","",INDEX(Setup!$C$25:$C$84,B16)) | P16: =IF(A16="","",IF(K16<>"",K16,D16)) | Q16: =IF(A16="",0,IF(C16="✗",0,IF(OR(C16="✓",AND(Setup!$D$7="Yes",P16<=TODAY())),IF(L16<>"",L16,F16),0))) | R16: =IF(A16="","",IF(M16<>"",M16,G16)) | S16: =IF(A16="","",IF(N16<>"",N16,H16)) | T16: =IF(A16="","",IF(C16="✗","Skipped",IF(Q16>0,"Paid","Upcoming"))) | U16: =IF(A16="",0,IF(C16="✗",0,IF(L16<>"",L16,F16)))
A17: =IFERROR(SMALL(Calc!$B$2:$BB$61,12),"") | B17: =IF(A17="","",ROUND(MOD(A17,1)*1000,0)) | D17: =IF(A17="","",INT(A17)) | E17: =IF(B17="","",INDEX(Setup!$D$25:$D$84,B17)) | F17: =IF(B17="","",INDEX(Setup!$E$25:$E$84,B17)) | G17: =IF(B17="","",INDEX(Setup!$I$25:$I$84,B17)&"") | H17: =IF(B17="","",INDEX(Setup!$J$25:$J$84,B17)&"") | I17: =IF(B17="","",INDEX(Setup!$C$25:$C$84,B17)) | P17: =IF(A17="","",IF(K17<>"",K17,D17)) | Q17: =IF(A17="",0,IF(C17="✗",0,IF(OR(C17="✓",AND(Setup!$D$7="Yes",P17<=TODAY())),IF(L17<>"",L17,F17),0))) | R17: =IF(A17="","",IF(M17<>"",M17,G17)) | S17: =IF(A17="","",IF(N17<>"",N17,H17)) | T17: =IF(A17="","",IF(C17="✗","Skipped",IF(Q17>0,"Paid","Upcoming"))) | U17: =IF(A17="",0,IF(C17="✗",0,IF(L17<>"",L17,F17)))
A18: =IFERROR(SMALL(Calc!$B$2:$BB$61,13),"") | B18: =IF(A18="","",ROUND(MOD(A18,1)*1000,0)) | D18: =IF(A18="","",INT(A18)) | E18: =IF(B18="","",INDEX(Setup!$D$25:$D$84,B18)) | F18: =IF(B18="","",INDEX(Setup!$E$25:$E$84,B18)) | G18: =IF(B18="","",INDEX(Setup!$I$25:$I$84,B18)&"") | H18: =IF(B18="","",INDEX(Setup!$J$25:$J$84,B18)&"") | I18: =IF(B18="","",INDEX(Setup!$C$25:$C$84,B18)) | P18: =IF(A18="","",IF(K18<>"",K18,D18)) | Q18: =IF(A18="",0,IF(C18="✗",0,IF(OR(C18="✓",AND(Setup!$D$7="Yes",P18<=TODAY())),IF(L18<>"",L18,F18),0))) | R18: =IF(A18="","",IF(M18<>"",M18,G18)) | S18: =IF(A18="","",IF(N18<>"",N18,H18)) | T18: =IF(A18="","",IF(C18="✗","Skipped",IF(Q18>0,"Paid","Upcoming"))) | U18: =IF(A18="",0,IF(C18="✗",0,IF(L18<>"",L18,F18)))
A19: =IFERROR(SMALL(Calc!$B$2:$BB$61,14),"") | B19: =IF(A19="","",ROUND(MOD(A19,1)*1000,0)) | D19: =IF(A19="","",INT(A19)) | E19: =IF(B19="","",INDEX(Setup!$D$25:$D$84,B19)) | F19: =IF(B19="","",INDEX(Setup!$E$25:$E$84,B19)) | G19: =IF(B19="","",INDEX(Setup!$I$25:$I$84,B19)&"") | H19: =IF(B19="","",INDEX(Setup!$J$25:$J$84,B19)&"") | I19: =IF(B19="","",INDEX(Setup!$C$25:$C$84,B19)) | P19: =IF(A19="","",IF(K19<>"",K19,D19)) | Q19: =IF(A19="",0,IF(C19="✗",0,IF(OR(C19="✓",AND(Setup!$D$7="Yes",P19<=TODAY())),IF(L19<>"",L19,F19),0))) | R19: =IF(A19="","",IF(M19<>"",M19,G19)) | S19: =IF(A19="","",IF(N19<>"",N19,H19)) | T19: =IF(A19="","",IF(C19="✗","Skipped",IF(Q19>0,"Paid","Upcoming"))) | U19: =IF(A19="",0,IF(C19="✗",0,IF(L19<>"",L19,F19)))
A20: =IFERROR(SMALL(Calc!$B$2:$BB$61,15),"") | B20: =IF(A20="","",ROUND(MOD(A20,1)*1000,0)) | D20: =IF(A20="","",INT(A20)) | E20: =IF(B20="","",INDEX(Setup!$D$25:$D$84,B20)) | F20: =IF(B20="","",INDEX(Setup!$E$25:$E$84,B20)) | G20: =IF(B20="","",INDEX(Setup!$I$25:$I$84,B20)&"") | H20: =IF(B20="","",INDEX(Setup!$J$25:$J$84,B20)&"") | I20: =IF(B20="","",INDEX(Setup!$C$25:$C$84,B20)) | P20: =IF(A20="","",IF(K20<>"",K20,D20)) | Q20: =IF(A20="",0,IF(C20="✗",0,IF(OR(C20="✓",AND(Setup!$D$7="Yes",P20<=TODAY())),IF(L20<>"",L20,F20),0))) | R20: =IF(A20="","",IF(M20<>"",M20,G20)) | S20: =IF(A20="","",IF(N20<>"",N20,H20)) | T20: =IF(A20="","",IF(C20="✗","Skipped",IF(Q20>0,"Paid","Upcoming"))) | U20: =IF(A20="",0,IF(C20="✗",0,IF(L20<>"",L20,F20)))
A21: =IFERROR(SMALL(Calc!$B$2:$BB$61,16),"") | B21: =IF(A21="","",ROUND(MOD(A21,1)*1000,0)) | D21: =IF(A21="","",INT(A21)) | E21: =IF(B21="","",INDEX(Setup!$D$25:$D$84,B21)) | F21: =IF(B21="","",INDEX(Setup!$E$25:$E$84,B21)) | G21: =IF(B21="","",INDEX(Setup!$I$25:$I$84,B21)&"") | H21: =IF(B21="","",INDEX(Setup!$J$25:$J$84,B21)&"") | I21: =IF(B21="","",INDEX(Setup!$C$25:$C$84,B21)) | P21: =IF(A21="","",IF(K21<>"",K21,D21)) | Q21: =IF(A21="",0,IF(C21="✗",0,IF(OR(C21="✓",AND(Setup!$D$7="Yes",P21<=TODAY())),IF(L21<>"",L21,F21),0))) | R21: =IF(A21="","",IF(M21<>"",M21,G21)) | S21: =IF(A21="","",IF(N21<>"",N21,H21)) | T21: =IF(A21="","",IF(C21="✗","Skipped",IF(Q21>0,"Paid","Upcoming"))) | U21: =IF(A21="",0,IF(C21="✗",0,IF(L21<>"",L21,F21)))
A22: =IFERROR(SMALL(Calc!$B$2:$BB$61,17),"") | B22: =IF(A22="","",ROUND(MOD(A22,1)*1000,0)) | D22: =IF(A22="","",INT(A22)) | E22: =IF(B22="","",INDEX(Setup!$D$25:$D$84,B22)) | F22: =IF(B22="","",INDEX(Setup!$E$25:$E$84,B22)) | G22: =IF(B22="","",INDEX(Setup!$I$25:$I$84,B22)&"") | H22: =IF(B22="","",INDEX(Setup!$J$25:$J$84,B22)&"") | I22: =IF(B22="","",INDEX(Setup!$C$25:$C$84,B22)) | P22: =IF(A22="","",IF(K22<>"",K22,D22)) | Q22: =IF(A22="",0,IF(C22="✗",0,IF(OR(C22="✓",AND(Setup!$D$7="Yes",P22<=TODAY())),IF(L22<>"",L22,F22),0))) | R22: =IF(A22="","",IF(M22<>"",M22,G22)) | S22: =IF(A22="","",IF(N22<>"",N22,H22)) | T22: =IF(A22="","",IF(C22="✗","Skipped",IF(Q22>0,"Paid","Upcoming"))) | U22: =IF(A22="",0,IF(C22="✗",0,IF(L22<>"",L22,F22)))
A23: =IFERROR(SMALL(Calc!$B$2:$BB$61,18),"") | B23: =IF(A23="","",ROUND(MOD(A23,1)*1000,0)) | D23: =IF(A23="","",INT(A23)) | E23: =IF(B23="","",INDEX(Setup!$D$25:$D$84,B23)) | F23: =IF(B23="","",INDEX(Setup!$E$25:$E$84,B23)) | G23: =IF(B23="","",INDEX(Setup!$I$25:$I$84,B23)&"") | H23: =IF(B23="","",INDEX(Setup!$J$25:$J$84,B23)&"") | I23: =IF(B23="","",INDEX(Setup!$C$25:$C$84,B23)) | P23: =IF(A23="","",IF(K23<>"",K23,D23)) | Q23: =IF(A23="",0,IF(C23="✗",0,IF(OR(C23="✓",AND(Setup!$D$7="Yes",P23<=TODAY())),IF(L23<>"",L23,F23),0))) | R23: =IF(A23="","",IF(M23<>"",M23,G23)) | S23: =IF(A23="","",IF(N23<>"",N23,H23)) | T23: =IF(A23="","",IF(C23="✗","Skipped",IF(Q23>0,"Paid","Upcoming"))) | U23: =IF(A23="",0,IF(C23="✗",0,IF(L23<>"",L23,F23)))
A24: =IFERROR(SMALL(Calc!$B$2:$BB$61,19),"") | B24: =IF(A24="","",ROUND(MOD(A24,1)*1000,0)) | D24: =IF(A24="","",INT(A24)) | E24: =IF(B24="","",INDEX(Setup!$D$25:$D$84,B24)) | F24: =IF(B24="","",INDEX(Setup!$E$25:$E$84,B24)) | G24: =IF(B24="","",INDEX(Setup!$I$25:$I$84,B24)&"") | H24: =IF(B24="","",INDEX(Setup!$J$25:$J$84,B24)&"") | I24: =IF(B24="","",INDEX(Setup!$C$25:$C$84,B24)) | P24: =IF(A24="","",IF(K24<>"",K24,D24)) | Q24: =IF(A24="",0,IF(C24="✗",0,IF(OR(C24="✓",AND(Setup!$D$7="Yes",P24<=TODAY())),IF(L24<>"",L24,F24),0))) | R24: =IF(A24="","",IF(M24<>"",M24,G24)) | S24: =IF(A24="","",IF(N24<>"",N24,H24)) | T24: =IF(A24="","",IF(C24="✗","Skipped",IF(Q24>0,"Paid","Upcoming"))) | U24: =IF(A24="",0,IF(C24="✗",0,IF(L24<>"",L24,F24)))
A25: =IFERROR(SMALL(Calc!$B$2:$BB$61,20),"") | B25: =IF(A25="","",ROUND(MOD(A25,1)*1000,0)) | D25: =IF(A25="","",INT(A25)) | E25: =IF(B25="","",INDEX(Setup!$D$25:$D$84,B25)) | F25: =IF(B25="","",INDEX(Setup!$E$25:$E$84,B25)) | G25: =IF(B25="","",INDEX(Setup!$I$25:$I$84,B25)&"") | H25: =IF(B25="","",INDEX(Setup!$J$25:$J$84,B25)&"") | I25: =IF(B25="","",INDEX(Setup!$C$25:$C$84,B25)) | P25: =IF(A25="","",IF(K25<>"",K25,D25)) | Q25: =IF(A25="",0,IF(C25="✗",0,IF(OR(C25="✓",AND(Setup!$D$7="Yes",P25<=TODAY())),IF(L25<>"",L25,F25),0))) | R25: =IF(A25="","",IF(M25<>"",M25,G25)) | S25: =IF(A25="","",IF(N25<>"",N25,H25)) | T25: =IF(A25="","",IF(C25="✗","Skipped",IF(Q25>0,"Paid","Upcoming"))) | U25: =IF(A25="",0,IF(C25="✗",0,IF(L25<>"",L25,F25)))
A26: =IFERROR(SMALL(Calc!$B$2:$BB$61,21),"") | B26: =IF(A26="","",ROUND(MOD(A26,1)*1000,0)) | D26: =IF(A26="","",INT(A26)) | E26: =IF(B26="","",INDEX(Setup!$D$25:$D$84,B26)) | F26: =IF(B26="","",INDEX(Setup!$E$25:$E$84,B26)) | G26: =IF(B26="","",INDEX(Setup!$I$25:$I$84,B26)&"") | H26: =IF(B26="","",INDEX(Setup!$J$25:$J$84,B26)&"") | I26: =IF(B26="","",INDEX(Setup!$C$25:$C$84,B26)) | P26: =IF(A26="","",IF(K26<>"",K26,D26)) | Q26: =IF(A26="",0,IF(C26="✗",0,IF(OR(C26="✓",AND(Setup!$D$7="Yes",P26<=TODAY())),IF(L26<>"",L26,F26),0))) | R26: =IF(A26="","",IF(M26<>"",M26,G26)) | S26: =IF(A26="","",IF(N26<>"",N26,H26)) | T26: =IF(A26="","",IF(C26="✗","Skipped",IF(Q26>0,"Paid","Upcoming"))) | U26: =IF(A26="",0,IF(C26="✗",0,IF(L26<>"",L26,F26)))
A27: =IFERROR(SMALL(Calc!$B$2:$BB$61,22),"") | B27: =IF(A27="","",ROUND(MOD(A27,1)*1000,0)) | D27: =IF(A27="","",INT(A27)) | E27: =IF(B27="","",INDEX(Setup!$D$25:$D$84,B27)) | F27: =IF(B27="","",INDEX(Setup!$E$25:$E$84,B27)) | G27: =IF(B27="","",INDEX(Setup!$I$25:$I$84,B27)&"") | H27: =IF(B27="","",INDEX(Setup!$J$25:$J$84,B27)&"") | I27: =IF(B27="","",INDEX(Setup!$C$25:$C$84,B27)) | P27: =IF(A27="","",IF(K27<>"",K27,D27)) | Q27: =IF(A27="",0,IF(C27="✗",0,IF(OR(C27="✓",AND(Setup!$D$7="Yes",P27<=TODAY())),IF(L27<>"",L27,F27),0))) | R27: =IF(A27="","",IF(M27<>"",M27,G27)) | S27: =IF(A27="","",IF(N27<>"",N27,H27)) | T27: =IF(A27="","",IF(C27="✗","Skipped",IF(Q27>0,"Paid","Upcoming"))) | U27: =IF(A27="",0,IF(C27="✗",0,IF(L27<>"",L27,F27)))
A28: =IFERROR(SMALL(Calc!$B$2:$BB$61,23),"") | B28: =IF(A28="","",ROUND(MOD(A28,1)*1000,0)) | D28: =IF(A28="","",INT(A28)) | E28: =IF(B28="","",INDEX(Setup!$D$25:$D$84,B28)) | F28: =IF(B28="","",INDEX(Setup!$E$25:$E$84,B28)) | G28: =IF(B28="","",INDEX(Setup!$I$25:$I$84,B28)&"") | H28: =IF(B28="","",INDEX(Setup!$J$25:$J$84,B28)&"") | I28: =IF(B28="","",INDEX(Setup!$C$25:$C$84,B28)) | P28: =IF(A28="","",IF(K28<>"",K28,D28)) | Q28: =IF(A28="",0,IF(C28="✗",0,IF(OR(C28="✓",AND(Setup!$D$7="Yes",P28<=TODAY())),IF(L28<>"",L28,F28),0))) | R28: =IF(A28="","",IF(M28<>"",M28,G28)) | S28: =IF(A28="","",IF(N28<>"",N28,H28)) | T28: =IF(A28="","",IF(C28="✗","Skipped",IF(Q28>0,"Paid","Upcoming"))) | U28: =IF(A28="",0,IF(C28="✗",0,IF(L28<>"",L28,F28)))
A29: =IFERROR(SMALL(Calc!$B$2:$BB$61,24),"") | B29: =IF(A29="","",ROUND(MOD(A29,1)*1000,0)) | D29: =IF(A29="","",INT(A29)) | E29: =IF(B29="","",INDEX(Setup!$D$25:$D$84,B29)) | F29: =IF(B29="","",INDEX(Setup!$E$25:$E$84,B29)) | G29: =IF(B29="","",INDEX(Setup!$I$25:$I$84,B29)&"") | H29: =IF(B29="","",INDEX(Setup!$J$25:$J$84,B29)&"") | I29: =IF(B29="","",INDEX(Setup!$C$25:$C$84,B29)) | P29: =IF(A29="","",IF(K29<>"",K29,D29)) | Q29: =IF(A29="",0,IF(C29="✗",0,IF(OR(C29="✓",AND(Setup!$D$7="Yes",P29<=TODAY())),IF(L29<>"",L29,F29),0))) | R29: =IF(A29="","",IF(M29<>"",M29,G29)) | S29: =IF(A29="","",IF(N29<>"",N29,H29)) | T29: =IF(A29="","",IF(C29="✗","Skipped",IF(Q29>0,"Paid","Upcoming"))) | U29: =IF(A29="",0,IF(C29="✗",0,IF(L29<>"",L29,F29)))
A30: =IFERROR(SMALL(Calc!$B$2:$BB$61,25),"") | B30: =IF(A30="","",ROUND(MOD(A30,1)*1000,0)) | D30: =IF(A30="","",INT(A30)) | E30: =IF(B30="","",INDEX(Setup!$D$25:$D$84,B30)) | F30: =IF(B30="","",INDEX(Setup!$E$25:$E$84,B30)) | G30: =IF(B30="","",INDEX(Setup!$I$25:$I$84,B30)&"") | H30: =IF(B30="","",INDEX(Setup!$J$25:$J$84,B30)&"") | I30: =IF(B30="","",INDEX(Setup!$C$25:$C$84,B30)) | P30: =IF(A30="","",IF(K30<>"",K30,D30)) | Q30: =IF(A30="",0,IF(C30="✗",0,IF(OR(C30="✓",AND(Setup!$D$7="Yes",P30<=TODAY())),IF(L30<>"",L30,F30),0))) | R30: =IF(A30="","",IF(M30<>"",M30,G30)) | S30: =IF(A30="","",IF(N30<>"",N30,H30)) | T30: =IF(A30="","",IF(C30="✗","Skipped",IF(Q30>0,"Paid","Upcoming"))) | U30: =IF(A30="",0,IF(C30="✗",0,IF(L30<>"",L30,F30)))
A31: =IFERROR(SMALL(Calc!$B$2:$BB$61,26),"") | B31: =IF(A31="","",ROUND(MOD(A31,1)*1000,0)) | D31: =IF(A31="","",INT(A31)) | E31: =IF(B31="","",INDEX(Setup!$D$25:$D$84,B31)) | F31: =IF(B31="","",INDEX(Setup!$E$25:$E$84,B31)) | G31: =IF(B31="","",INDEX(Setup!$I$25:$I$84,B31)&"") | H31: =IF(B31="","",INDEX(Setup!$J$25:$J$84,B31)&"") | I31: =IF(B31="","",INDEX(Setup!$C$25:$C$84,B31)) | P31: =IF(A31="","",IF(K31<>"",K31,D31)) | Q31: =IF(A31="",0,IF(C31="✗",0,IF(OR(C31="✓",AND(Setup!$D$7="Yes",P31<=TODAY())),IF(L31<>"",L31,F31),0))) | R31: =IF(A31="","",IF(M31<>"",M31,G31)) | S31: =IF(A31="","",IF(N31<>"",N31,H31)) | T31: =IF(A31="","",IF(C31="✗","Skipped",IF(Q31>0,"Paid","Upcoming"))) | U31: =IF(A31="",0,IF(C31="✗",0,IF(L31<>"",L31,F31)))
A32: =IFERROR(SMALL(Calc!$B$2:$BB$61,27),"") | B32: =IF(A32="","",ROUND(MOD(A32,1)*1000,0)) | D32: =IF(A32="","",INT(A32)) | E32: =IF(B32="","",INDEX(Setup!$D$25:$D$84,B32)) | F32: =IF(B32="","",INDEX(Setup!$E$25:$E$84,B32)) | G32: =IF(B32="","",INDEX(Setup!$I$25:$I$84,B32)&"") | H32: =IF(B32="","",INDEX(Setup!$J$25:$J$84,B32)&"") | I32: =IF(B32="","",INDEX(Setup!$C$25:$C$84,B32)) | P32: =IF(A32="","",IF(K32<>"",K32,D32)) | Q32: =IF(A32="",0,IF(C32="✗",0,IF(OR(C32="✓",AND(Setup!$D$7="Yes",P32<=TODAY())),IF(L32<>"",L32,F32),0))) | R32: =IF(A32="","",IF(M32<>"",M32,G32)) | S32: =IF(A32="","",IF(N32<>"",N32,H32)) | T32: =IF(A32="","",IF(C32="✗","Skipped",IF(Q32>0,"Paid","Upcoming"))) | U32: =IF(A32="",0,IF(C32="✗",0,IF(L32<>"",L32,F32)))
A33: =IFERROR(SMALL(Calc!$B$2:$BB$61,28),"") | B33: =IF(A33="","",ROUND(MOD(A33,1)*1000,0)) | D33: =IF(A33="","",INT(A33)) | E33: =IF(B33="","",INDEX(Setup!$D$25:$D$84,B33)) | F33: =IF(B33="","",INDEX(Setup!$E$25:$E$84,B33)) | G33: =IF(B33="","",INDEX(Setup!$I$25:$I$84,B33)&"") | H33: =IF(B33="","",INDEX(Setup!$J$25:$J$84,B33)&"") | I33: =IF(B33="","",INDEX(Setup!$C$25:$C$84,B33)) | P33: =IF(A33="","",IF(K33<>"",K33,D33)) | Q33: =IF(A33="",0,IF(C33="✗",0,IF(OR(C33="✓",AND(Setup!$D$7="Yes",P33<=TODAY())),IF(L33<>"",L33,F33),0))) | R33: =IF(A33="","",IF(M33<>"",M33,G33)) | S33: =IF(A33="","",IF(N33<>"",N33,H33)) | T33: =IF(A33="","",IF(C33="✗","Skipped",IF(Q33>0,"Paid","Upcoming"))) | U33: =IF(A33="",0,IF(C33="✗",0,IF(L33<>"",L33,F33)))
A34: =IFERROR(SMALL(Calc!$B$2:$BB$61,29),"") | B34: =IF(A34="","",ROUND(MOD(A34,1)*1000,0)) | D34: =IF(A34="","",INT(A34)) | E34: =IF(B34="","",INDEX(Setup!$D$25:$D$84,B34)) | F34: =IF(B34="","",INDEX(Setup!$E$25:$E$84,B34)) | G34: =IF(B34="","",INDEX(Setup!$I$25:$I$84,B34)&"") | H34: =IF(B34="","",INDEX(Setup!$J$25:$J$84,B34)&"") | I34: =IF(B34="","",INDEX(Setup!$C$25:$C$84,B34)) | P34: =IF(A34="","",IF(K34<>"",K34,D34)) | Q34: =IF(A34="",0,IF(C34="✗",0,IF(OR(C34="✓",AND(Setup!$D$7="Yes",P34<=TODAY())),IF(L34<>"",L34,F34),0))) | R34: =IF(A34="","",IF(M34<>"",M34,G34)) | S34: =IF(A34="","",IF(N34<>"",N34,H34)) | T34: =IF(A34="","",IF(C34="✗","Skipped",IF(Q34>0,"Paid","Upcoming"))) | U34: =IF(A34="",0,IF(C34="✗",0,IF(L34<>"",L34,F34)))
A35: =IFERROR(SMALL(Calc!$B$2:$BB$61,30),"") | B35: =IF(A35="","",ROUND(MOD(A35,1)*1000,0)) | D35: =IF(A35="","",INT(A35)) | E35: =IF(B35="","",INDEX(Setup!$D$25:$D$84,B35)) | F35: =IF(B35="","",INDEX(Setup!$E$25:$E$84,B35)) | G35: =IF(B35="","",INDEX(Setup!$I$25:$I$84,B35)&"") | H35: =IF(B35="","",INDEX(Setup!$J$25:$J$84,B35)&"") | I35: =IF(B35="","",INDEX(Setup!$C$25:$C$84,B35)) | P35: =IF(A35="","",IF(K35<>"",K35,D35)) | Q35: =IF(A35="",0,IF(C35="✗",0,IF(OR(C35="✓",AND(Setup!$D$7="Yes",P35<=TODAY())),IF(L35<>"",L35,F35),0))) | R35: =IF(A35="","",IF(M35<>"",M35,G35)) | S35: =IF(A35="","",IF(N35<>"",N35,H35)) | T35: =IF(A35="","",IF(C35="✗","Skipped",IF(Q35>0,"Paid","Upcoming"))) | U35: =IF(A35="",0,IF(C35="✗",0,IF(L35<>"",L35,F35)))
A36: =IFERROR(SMALL(Calc!$B$2:$BB$61,31),"") | B36: =IF(A36="","",ROUND(MOD(A36,1)*1000,0)) | D36: =IF(A36="","",INT(A36)) | E36: =IF(B36="","",INDEX(Setup!$D$25:$D$84,B36)) | F36: =IF(B36="","",INDEX(Setup!$E$25:$E$84,B36)) | G36: =IF(B36="","",INDEX(Setup!$I$25:$I$84,B36)&"") | H36: =IF(B36="","",INDEX(Setup!$J$25:$J$84,B36)&"") | I36: =IF(B36="","",INDEX(Setup!$C$25:$C$84,B36)) | P36: =IF(A36="","",IF(K36<>"",K36,D36)) | Q36: =IF(A36="",0,IF(C36="✗",0,IF(OR(C36="✓",AND(Setup!$D$7="Yes",P36<=TODAY())),IF(L36<>"",L36,F36),0))) | R36: =IF(A36="","",IF(M36<>"",M36,G36)) | S36: =IF(A36="","",IF(N36<>"",N36,H36)) | T36: =IF(A36="","",IF(C36="✗","Skipped",IF(Q36>0,"Paid","Upcoming"))) | U36: =IF(A36="",0,IF(C36="✗",0,IF(L36<>"",L36,F36)))
A37: =IFERROR(SMALL(Calc!$B$2:$BB$61,32),"") | B37: =IF(A37="","",ROUND(MOD(A37,1)*1000,0)) | D37: =IF(A37="","",INT(A37)) | E37: =IF(B37="","",INDEX(Setup!$D$25:$D$84,B37)) | F37: =IF(B37="","",INDEX(Setup!$E$25:$E$84,B37)) | G37: =IF(B37="","",INDEX(Setup!$I$25:$I$84,B37)&"") | H37: =IF(B37="","",INDEX(Setup!$J$25:$J$84,B37)&"") | I37: =IF(B37="","",INDEX(Setup!$C$25:$C$84,B37)) | P37: =IF(A37="","",IF(K37<>"",K37,D37)) | Q37: =IF(A37="",0,IF(C37="✗",0,IF(OR(C37="✓",AND(Setup!$D$7="Yes",P37<=TODAY())),IF(L37<>"",L37,F37),0))) | R37: =IF(A37="","",IF(M37<>"",M37,G37)) | S37: =IF(A37="","",IF(N37<>"",N37,H37)) | T37: =IF(A37="","",IF(C37="✗","Skipped",IF(Q37>0,"Paid","Upcoming"))) | U37: =IF(A37="",0,IF(C37="✗",0,IF(L37<>"",L37,F37)))
A38: =IFERROR(SMALL(Calc!$B$2:$BB$61,33),"") | B38: =IF(A38="","",ROUND(MOD(A38,1)*1000,0)) | D38: =IF(A38="","",INT(A38)) | E38: =IF(B38="","",INDEX(Setup!$D$25:$D$84,B38)) | F38: =IF(B38="","",INDEX(Setup!$E$25:$E$84,B38)) | G38: =IF(B38="","",INDEX(Setup!$I$25:$I$84,B38)&"") | H38: =IF(B38="","",INDEX(Setup!$J$25:$J$84,B38)&"") | I38: =IF(B38="","",INDEX(Setup!$C$25:$C$84,B38)) | P38: =IF(A38="","",IF(K38<>"",K38,D38)) | Q38: =IF(A38="",0,IF(C38="✗",0,IF(OR(C38="✓",AND(Setup!$D$7="Yes",P38<=TODAY())),IF(L38<>"",L38,F38),0))) | R38: =IF(A38="","",IF(M38<>"",M38,G38)) | S38: =IF(A38="","",IF(N38<>"",N38,H38)) | T38: =IF(A38="","",IF(C38="✗","Skipped",IF(Q38>0,"Paid","Upcoming"))) | U38: =IF(A38="",0,IF(C38="✗",0,IF(L38<>"",L38,F38)))
A39: =IFERROR(SMALL(Calc!$B$2:$BB$61,34),"") | B39: =IF(A39="","",ROUND(MOD(A39,1)*1000,0)) | D39: =IF(A39="","",INT(A39)) | E39: =IF(B39="","",INDEX(Setup!$D$25:$D$84,B39)) | F39: =IF(B39="","",INDEX(Setup!$E$25:$E$84,B39)) | G39: =IF(B39="","",INDEX(Setup!$I$25:$I$84,B39)&"") | H39: =IF(B39="","",INDEX(Setup!$J$25:$J$84,B39)&"") | I39: =IF(B39="","",INDEX(Setup!$C$25:$C$84,B39)) | P39: =IF(A39="","",IF(K39<>"",K39,D39)) | Q39: =IF(A39="",0,IF(C39="✗",0,IF(OR(C39="✓",AND(Setup!$D$7="Yes",P39<=TODAY())),IF(L39<>"",L39,F39),0))) | R39: =IF(A39="","",IF(M39<>"",M39,G39)) | S39: =IF(A39="","",IF(N39<>"",N39,H39)) | T39: =IF(A39="","",IF(C39="✗","Skipped",IF(Q39>0,"Paid","Upcoming"))) | U39: =IF(A39="",0,IF(C39="✗",0,IF(L39<>"",L39,F39)))
A40: =IFERROR(SMALL(Calc!$B$2:$BB$61,35),"") | B40: =IF(A40="","",ROUND(MOD(A40,1)*1000,0)) | D40: =IF(A40="","",INT(A40)) | E40: =IF(B40="","",INDEX(Setup!$D$25:$D$84,B40)) | F40: =IF(B40="","",INDEX(Setup!$E$25:$E$84,B40)) | G40: =IF(B40="","",INDEX(Setup!$I$25:$I$84,B40)&"") | H40: =IF(B40="","",INDEX(Setup!$J$25:$J$84,B40)&"") | I40: =IF(B40="","",INDEX(Setup!$C$25:$C$84,B40)) | P40: =IF(A40="","",IF(K40<>"",K40,D40)) | Q40: =IF(A40="",0,IF(C40="✗",0,IF(OR(C40="✓",AND(Setup!$D$7="Yes",P40<=TODAY())),IF(L40<>"",L40,F40),0))) | R40: =IF(A40="","",IF(M40<>"",M40,G40)) | S40: =IF(A40="","",IF(N40<>"",N40,H40)) | T40: =IF(A40="","",IF(C40="✗","Skipped",IF(Q40>0,"Paid","Upcoming"))) | U40: =IF(A40="",0,IF(C40="✗",0,IF(L40<>"",L40,F40)))
A41: =IFERROR(SMALL(Calc!$B$2:$BB$61,36),"") | B41: =IF(A41="","",ROUND(MOD(A41,1)*1000,0)) | D41: =IF(A41="","",INT(A41)) | E41: =IF(B41="","",INDEX(Setup!$D$25:$D$84,B41)) | F41: =IF(B41="","",INDEX(Setup!$E$25:$E$84,B41)) | G41: =IF(B41="","",INDEX(Setup!$I$25:$I$84,B41)&"") | H41: =IF(B41="","",INDEX(Setup!$J$25:$J$84,B41)&"") | I41: =IF(B41="","",INDEX(Setup!$C$25:$C$84,B41)) | P41: =IF(A41="","",IF(K41<>"",K41,D41)) | Q41: =IF(A41="",0,IF(C41="✗",0,IF(OR(C41="✓",AND(Setup!$D$7="Yes",P41<=TODAY())),IF(L41<>"",L41,F41),0))) | R41: =IF(A41="","",IF(M41<>"",M41,G41)) | S41: =IF(A41="","",IF(N41<>"",N41,H41)) | T41: =IF(A41="","",IF(C41="✗","Skipped",IF(Q41>0,"Paid","Upcoming"))) | U41: =IF(A41="",0,IF(C41="✗",0,IF(L41<>"",L41,F41)))
...

Sheet Manual Log
B2: MANUAL LOG
B3: Log variable expenses, irregular income, one-off bills and money transfers here (or paste from your bank). Category 'Transfer' moves money between accounts only.
B4: MANUAL LOG
B5: DATE | C5: CATEGORY | D5: SUB-CATEGORY | E5: AMOUNT | F5: FROM ACCOUNT | G5: TO ACCOUNT | H5: DESCRIPTION
B6: 46024 | C6: Variable Exp | D6: Groceries | E6: 53.16 | F6: Checking 2 | G6: N/A
B7: 46024 | C7: Variable Exp | D7: Groceries | E7: 123.55 | F7: Credit Card 1 | G7: N/A
B8: 46024 | C8: Variable Exp | D8: Pets | E8: 68.29 | F8: Credit Card 1 | G8: N/A
B9: 46025 | C9: Variable Exp | D9: Groceries | E9: 67.86 | F9: Checking 2 | G9: N/A
B10: 46026 | C10: Variable Exp | D10: Eating Out | E10: 56.97 | F10: Credit Card 2 | G10: N/A
B11: 46027 | C11: Variable Exp | D11: School | E11: 113.99 | F11: Checking 2 | G11: N/A
B12: 46030 | C12: Variable Exp | D12: Eating Out | E12: 21.12 | F12: Credit Card 2 | G12: N/A
B13: 46030 | C13: Variable Exp | D13: Eating Out | E13: 60.25 | F13: Credit Card 1 | G13: N/A
B14: 46032 | C14: Variable Exp | D14: Eating Out | E14: 46.08 | F14: Credit Card 1 | G14: N/A
B15: 46033 | C15: Variable Exp | D15: Gifts | E15: 68.67 | F15: Checking 2 | G15: N/A
B16: 46033 | C16: Variable Exp | D16: Groceries | E16: 135.05 | F16: Checking 2 | G16: N/A
B17: 46033 | C17: Variable Exp | D17: Transportation | E17: 62.83 | F17: Checking 1 | G17: N/A
... B30: 46045 | C30: Variable Exp | D30: Transportation | E30: 65.09 | F30: Credit Card 1 | G30: N/A
B31: 46047 | C31: Transfer | E31: 300 | F31: Checking 2 | G31: Checking 1 | H31: Move to main account
B32: 46047 | C32: Variable Exp | D32: Entertainment | E32: 35.71 | F32: Checking 2 | G32: N/A
B33: 46047 | C33: Variable Exp | D33: Hair/Beauty | E33: 46.74 | F33: Checking 1 | G33: N/A
B34: 46049 | C34: Variable Exp | D34: Other | E34: 13.74 | F34: Checking 1 | G34: N/A
B35: 46054 | C35: Variable Exp | D35: Groceries | E35: 134.36 | F35: Checking 1 | G35: N/A
B36: 46055 | C36: Variable Exp | D36: Eating Out | E36: 32.62 | F36: Checking 1 | G36: N/A
B37: 46055 | C37: Variable Exp | D37: Groceries | E37: 114.46 | F37: Checking 1 | G37: N/A
B38: 46056 | C38: Variable Exp | D38: Eating Out | E38: 29.15 | F38: Checking 2 | G38: N/A
B39: 46058 | C39: Variable Exp | D39: Eating Out | E39: 67.47 | F39: Checking 2 | G39: N/A
B40: 46058 | C40: Variable Exp | D40: Shopping | E40: 34.54 | F40: Credit Card 2 | G40: N/A
B41: 46058 | C41: Variable Exp | D41: Transportation | E41: 61.07 | F41: Credit Card 1 | G41: N/A
B42: 46059 | C42: Variable Exp | D42: Groceries | E42: 103.04 | F42: Checking 2 | G42: N/A
B43: 46060 | C43: Variable Exp | D43: Pets | E43: 28.03 | F43: Credit Card 2 | G43: N/A
... B61: 46076 | C61: Variable Exp | D61: Shopping | E61: 72.76 | F61: Checking 1 | G61: N/A
B62: 46078 | C62: Transfer | E62: 300 | F62: Checking 2 | G62: Checking 1 | H62: Move to main account
B63: 46080 | C63: Variable Exp | D63: Eating Out | E63: 46.84 | F63: Checking 1 | G63: N/A
B64: 46082 | C64: Variable Exp | D64: Transportation | E64: 65.56 | F64: Checking 2 | G64: N/A
B65: 46085 | C65: Variable Exp | D65: Groceries | E65: 125.65 | F65: Checking 2 | G65: N/A
B66: 46086 | C66: Variable Exp | D66: Eating Out | E66: 64.23 | F66: Credit Card 1 | G66: N/A
B67: 46086 | C67: Variable Exp | D67: Groceries | E67: 54.71 | F67: Checking 1 | G67: N/A
B68: 46086 | C68: Variable Exp | D68: Groceries | E68: 105.27 | F68: Checking 1 | G68: N/A
B69: 46087 | C69: Variable Exp | D69: Eating Out | E69: 41.83 | F69: Credit Card 2 | G69: N/A
B70: 46088 | C70: Variable Exp | D70: School | E70: 73.44 | F70: Credit Card 1 | G70: N/A
...

Sheet Accounts
B2: ACCOUNTS
B3: Balances update from paid items in Payments + everything in the Manual Log.
B4: ACCOUNT BALANCES
B5: ACCOUNT | C5: OPENING | D5: MONEY IN | E5: MONEY OUT | F5: CURRENT BALANCE
B6: =IF(Setup!F6="","",Setup!F6) | C6: =IF(B6="","",Setup!G6) | D6: =IF(B6="","",SUMIFS(Payments!$Q$6:$Q$1205,Payments!$S$6:$S$1205,B6)+SUMIFS('Manual Log'!$E$6:$E$1005,'Manual Log'!$G$6:$G$1005,B6)) | E6: =IF(B6="","",SUMIFS(Payments!$Q$6:$Q$1205,Payments!$R$6:$R$1205,B6)+SUMIFS('Manual Log'!$E$6:$E$1005,'Manual Log'!$F$6:$F$1005,B6)) | F6: =IF(B6="","",C6+D6-E6)
B7: =IF(Setup!F7="","",Setup!F7) | C7: =IF(B7="","",Setup!G7) | D7: =IF(B7="","",SUMIFS(Payments!$Q$6:$Q$1205,Payments!$S$6:$S$1205,B7)+SUMIFS('Manual Log'!$E$6:$E$1005,'Manual Log'!$G$6:$G$1005,B7)) | E7: =IF(B7="","",SUMIFS(Payments!$Q$6:$Q$1205,Payments!$R$6:$R$1205,B7)+SUMIFS('Manual Log'!$E$6:$E$1005,'Manual Log'!$F$6:$F$1005,B7)) | F7: =IF(B7="","",C7+D7-E7)
B8: =IF(Setup!F8="","",Setup!F8) | C8: =IF(B8="","",Setup!G8) | D8: =IF(B8="","",SUMIFS(Payments!$Q$6:$Q$1205,Payments!$S$6:$S$1205,B8)+SUMIFS('Manual Log'!$E$6:$E$1005,'Manual Log'!$G$6:$G$1005,B8)) | E8: =IF(B8="","",SUMIFS(Payments!$Q$6:$Q$1205,Payments!$R$6:$R$1205,B8)+SUMIFS('Manual Log'!$E$6:$E$1005,'Manual Log'!$F$6:$F$1005,B8)) | F8: =IF(B8="","",C8+D8-E8)
B9: =IF(Setup!F9="","",Setup!F9) | C9: =IF(B9="","",Setup!G9) | D9: =IF(B9="","",SUMIFS(Payments!$Q$6:$Q$1205,Payments!$S$6:$S$1205,B9)+SUMIFS('Manual Log'!$E$6:$E$1005,'Manual Log'!$G$6:$G$1005,B9)) | E9: =IF(B9="","",SUMIFS(Payments!$Q$6:$Q$1205,Payments!$R$6:$R$1205,B9)+SUMIFS('Manual Log'!$E$6:$E$1005,'Manual Log'!$F$6:$F$1005,B9)) | F9: =IF(B9="","",C9+D9-E9)
B10: =IF(Setup!F10="","",Setup!F10) | C10: =IF(B10="","",Setup!G10) | D10: =IF(B10="","",SUMIFS(Payments!$Q$6:$Q$1205,Payments!$S$6:$S$1205,B10)+SUMIFS('Manual Log'!$E$6:$E$1005,'Manual Log'!$G$6:$G$1005,B10)) | E10: =IF(B10="","",SUMIFS(Payments!$Q$6:$Q$1205,Payments!$R$6:$R$1205,B10)+SUMIFS('Manual Log'!$E$6:$E$1005,'Manual Log'!$F$6:$F$1005,B10)) | F10: =IF(B10="","",C10+D10-E10)
B11: =IF(Setup!F11="","",Setup!F11) | C11: =IF(B11="","",Setup!G11) | D11: =IF(B11="","",SUMIFS(Payments!$Q$6:$Q$1205,Payments!$S$6:$S$1205,B11)+SUMIFS('Manual Log'!$E$6:$E$1005,'Manual Log'!$G$6:$G$1005,B11)) | E11: =IF(B11="","",SUMIFS(Payments!$Q$6:$Q$1205,Payments!$R$6:$R$1205,B11)+SUMIFS('Manual Log'!$E$6:$E$1005,'Manual Log'!$F$6:$F$1005,B11)) | F11: =IF(B11="","",C11+D11-E11)
B12: =IF(Setup!F12="","",Setup!F12) | C12: =IF(B12="","",Setup!G12) | D12: =IF(B12="","",SUMIFS(Payments!$Q$6:$Q$1205,Payments!$S$6:$S$1205,B12)+SUMIFS('Manual Log'!$E$6:$E$1005,'Manual Log'!$G$6:$G$1005,B12)) | E12: =IF(B12="","",SUMIFS(Payments!$Q$6:$Q$1205,Payments!$R$6:$R$1205,B12)+SUMIFS('Manual Log'!$E$6:$E$1005,'Manual Log'!$F$6:$F$1005,B12)) | F12: =IF(B12="","",C12+D12-E12)
B13: =IF(Setup!F13="","",Setup!F13) | C13: =IF(B13="","",Setup!G13) | D13: =IF(B13="","",SUMIFS(Payments!$Q$6:$Q$1205,Payments!$S$6:$S$1205,B13)+SUMIFS('Manual Log'!$E$6:$E$1005,'Manual Log'!$G$6:$G$1005,B13)) | E13: =IF(B13="","",SUMIFS(Payments!$Q$6:$Q$1205,Payments!$R$6:$R$1205,B13)+SUMIFS('Manual Log'!$E$6:$E$1005,'Manual Log'!$F$6:$F$1005,B13)) | F13: =IF(B13="","",C13+D13-E13)
B14: =IF(Setup!F14="","",Setup!F14) | C14: =IF(B14="","",Setup!G14) | D14: =IF(B14="","",SUMIFS(Payments!$Q$6:$Q$1205,Payments!$S$6:$S$1205,B14)+SUMIFS('Manual Log'!$E$6:$E$1005,'Manual Log'!$G$6:$G$1005,B14)) | E14: =IF(B14="","",SUMIFS(Payments!$Q$6:$Q$1205,Payments!$R$6:$R$1205,B14)+SUMIFS('Manual Log'!$E$6:$E$1005,'Manual Log'!$F$6:$F$1005,B14)) | F14: =IF(B14="","",C14+D14-E14)
B15: =IF(Setup!F15="","",Setup!F15) | C15: =IF(B15="","",Setup!G15) | D15: =IF(B15="","",SUMIFS(Payments!$Q$6:$Q$1205,Payments!$S$6:$S$1205,B15)+SUMIFS('Manual Log'!$E$6:$E$1005,'Manual Log'!$G$6:$G$1005,B15)) | E15: =IF(B15="","",SUMIFS(Payments!$Q$6:$Q$1205,Payments!$R$6:$R$1205,B15)+SUMIFS('Manual Log'!$E$6:$E$1005,'Manual Log'!$F$6:$F$1005,B15)) | F15: =IF(B15="","",C15+D15-E15)
B16: =IF(Setup!F16="","",Setup!F16) | C16: =IF(B16="","",Setup!G16) | D16: =IF(B16="","",SUMIFS(Payments!$Q$6:$Q$1205,Payments!$S$6:$S$1205,B16)+SUMIFS('Manual Log'!$E$6:$E$1005,'Manual Log'!$G$6:$G$1005,B16)) | E16: =IF(B16="","",SUMIFS(Payments!$Q$6:$Q$1205,Payments!$R$6:$R$1205,B16)+SUMIFS('Manual Log'!$E$6:$E$1005,'Manual Log'!$F$6:$F$1005,B16)) | F16: =IF(B16="","",C16+D16-E16)
B17: =IF(Setup!F17="","",Setup!F17) | C17: =IF(B17="","",Setup!G17) | D17: =IF(B17="","",SUMIFS(Payments!$Q$6:$Q$1205,Payments!$S$6:$S$1205,B17)+SUMIFS('Manual Log'!$E$6:$E$1005,'Manual Log'!$G$6:$G$1005,B17)) | E17: =IF(B17="","",SUMIFS(Payments!$Q$6:$Q$1205,Payments!$R$6:$R$1205,B17)+SUMIFS('Manual Log'!$E$6:$E$1005,'Manual Log'!$F$6:$F$1005,B17)) | F17: =IF(B17="","",C17+D17-E17)
B18: NET WORTH | C18: =SUM(C6:C17) | D18: =SUM(D6:D17) | E18: =SUM(E6:E17) | F18: =SUM(F6:F17)

Sheet Dashboard
B2: BUDGET DASHBOARD | G2: PERIOD SUMMARY | L2: INCOME | Q2: SAVINGS
B3: =UPPER(C5)&" DASHBOARD" | I3: BUDGET | J3: ACTUAL | L3: =J5 | N3: BUDGET | O3: PROGRESS | Q3: =J7 | S3: BUDGET | T3: PROGRESS
B4: =TEXT(C6,"d mmm yyyy")&" – "&TEXT(C7,"d mmm yyyy") | G4: Start balance | I4: =C10 | J4: =C10 | N4: =I5 | O4: =IFERROR(J5/I5,0) | S4: =I7 | T4: =IFERROR(J7/I7,0)
B5: Budget period | C5: Monthly | G5: + Total income | I5: =C14 | J5: =D14
B6: Start date | C6: 46266 | G6: – Total expenses | I6: =SUM(C16:C19) | J6: =SUM(D16:D19) | L6: EXPENSES | Q6: LEFT TO SPEND
B7: End date | C7: =IF(C5="Custom",IF(C8="",C6,C8),IF(C5="Weekly",C6+6,IF(C5="Bi-weekly",C6+13,IF(C5="4-weekly",C6+27,IF(C5="Monthly",EDATE(C6,1)-1,IF(C5="Quarterly",EDATE(C6,3)-1,IF(C5="6-month",EDATE(C6,6)-1,EDATE(C6,12)-1))))))) | G7: – Total savings | I7: =C15 | J7: =D15 | L7: =J6 | N7: BUDGET | O7: PROGRESS | Q7: =J9 | S7: BUDGET | T7: PROGRESS
B8: Custom end date | D8: ← only for 'Custom' | G8: End balance | I8: =I4+I5-I6-I7 | J8: =J4+J5-J6-J7 | N8: =I6 | O8: =IFERROR(J6/I6,0) | S8: =I9 | T8: =IFERROR(J9/I9,0)
B9: Start balance override | D9: ← leave blank to roll over | G9: Left to spend | I9: =I5-I6-I7 | J9: =J5-J6-J7
B10: Start balance | C10: =IF(C9<>"",C9,Setup!$D$6+SUMIFS(Payments!$Q$6:$Q$1205,Payments!$I$6:$I$1205,"Income",Payments!$P$6:$P$1205,">="&Setup!$D$5,Payments!$P$6:$P$1205,"<"&C6)-SUMIFS(Payments!$Q$6:$Q$1205,Payments!$I$6:$I$1205,"<>Income",Payments!$I$6:$I$1205,"<>Transfer",Payments!$P$6:$P$1205,">="&Setup!$D$5,Payments!$P$6:$P$1205,"<"&C6)+SUMIFS('Manual Log'!$E$6:$E$1005,'Manual Log'!$C$6:$C$1005,"Income",'Manual Log'!$B$6:$B$1005,">="&Setup!$D$5,'Manual Log'!$B$6:$B$1005,"<"&C6)-SUMIFS('Manual Log'!$E$6:$E$1005,'Manual Log'!$C$6:$C$1005,"<>Income",'Manual Log'!$C$6:$C$1005,"<>Transfer",'Manual Log'!$B$6:$B$1005,">="&Setup!$D$5,'Manual Log'!$B$6:$B$1005,"<"&C6))
B12: BUDGET vs ACTUAL | G12: BUDGET vs ACTUAL | L12: EXPENSES BREAKDOWN | Q12: VARIABLE EXPENSES
B13: CATEGORY | C13: BUDGET | D13: ACTUAL | E13: PROGRESS
B14: Income | C14: =C30 | D14: =D30 | E14: =IFERROR(D14/C14,0)
B15: Savings | C15: =H30 | D15: =I30 | E15: =IFERROR(D15/C15,0)
B16: Bills | C16: =M30 | D16: =N30 | E16: =IFERROR(D16/C16,0)
B17: Debt | C17: =R30 | D17: =S30 | E17: =IFERROR(D17/C17,0)
B18: Subscriptions | C18: =C51 | D18: =D51 | E18: =IFERROR(D18/C18,0)
B19: Variable Exp. | C19: =H51 | D19: =I51 | E19: =IFERROR(D19/C19,0)
B20: REMAINING BUDGET (expenses) | E20: =SUM(C16:C19)-SUM(D16:D19)
B22: Pink text = over budget (expenses) or below target (income & savings).
B23: Actual = paid items in Payments + Manual Log entries in this period.
B27: INCOME | G27: SAVINGS | L27: BILLS | Q27: DEBT
B28: =D30 | G28: =I30 | L28: =N30 | Q28: =S30
B29: SUB-CATEGORY | C29: BUDGET | D29: ACTUAL | E29: DIFF | G29: SUB-CATEGORY | H29: BUDGET | I29: ACTUAL | J29: DIFF | L29: SUB-CATEGORY | M29: BUDGET | N29: ACTUAL | O29: REMAINING | Q29: SUB-CATEGORY | R29: BUDGET | S29: ACTUAL | T29: REMAINING | V29: =MAX(1,ROUNDUP(($C$7-$C$6+1)/31,0))
B30: TOTAL | C30: =SUM(C31:C40) | D30: =SUM(D31:D40) | E30: =SUM(E31:E40) | G30: TOTAL | H30: =SUM(H31:H40) | I30: =SUM(I31:I40) | J30: =SUM(J31:J40) | L30: TOTAL | M30: =SUM(M31:M45) | N30: =SUM(N31:N45) | O30: =SUM(O31:O45) | Q30: TOTAL | R30: =SUM(R31:R40) | S30: =SUM(S31:S40) | T30: =SUM(T31:T40)
B31: =IF(AC31="","",INDEX(Setup!$D$25:$D$84,AC31)) | C31: =IF(AC31="","",COUNTIFS(INDEX(Calc!$B$2:$BB$61,AC31,0),">="&$C$6,INDEX(Calc!$B$2:$BB$61,AC31,0),"<"&($C$7+1))*INDEX(Setup!$E$25:$E$84,AC31)) | D31: =IF(B31="","",SUMIFS(Payments!$Q$6:$Q$1205,Payments!$I$6:$I$1205,"Income",Payments!$E$6:$E$1205,B31,Payments!$P$6:$P$1205,">="&$C$6,Payments!$P$6:$P$1205,"<="&$C$7)+SUMIFS('Manual Log'!$E$6:$E$1005,'Manual Log'!$C$6:$C$1005,"Income",'Manual Log'!$D$6:$D$1005,B31,'Manual Log'!$B$6:$B$1005,">="&$C$6,'Manual Log'!$B$6:$B$1005,"<="&$C$7)) | E31: =IF(B31="","",D31-C31) | G31: =IF(AD31="","",INDEX(Setup!$D$25:$D$84,AD31)) | H31: =IF(AD31="","",COUNTIFS(INDEX(Calc!$B$2:$BB$61,AD31,0),">="&$C$6,INDEX(Calc!$B$2:$BB$61,AD31,0),"<"&($C$7+1))*INDEX(Setup!$E$25:$E$84,AD31)) | I31: =IF(G31="","",SUMIFS(Payments!$Q$6:$Q$1205,Payments!$I$6:$I$1205,"Savings",Payments!$E$6:$E$1205,G31,Payments!$P$6:$P$1205,">="&$C$6,Payments!$P$6:$P$1205,"<="&$C$7)+SUMIFS('Manual Log'!$E$6:$E$1005,'Manual Log'!$C$6:$C$1005,"Savings",'Manual Log'!$D$6:$D$1005,G31,'Manual Log'!$B$6:$B$1005,">="&$C$6,'Manual Log'!$B$6:$B$1005,"<="&$C$7)) | J31: =IF(G31="","",I31-H31) | L31: =IF(AE31="","",INDEX(Setup!$D$25:$D$84,AE31)) | M31: =IF(AE31="","",COUNTIFS(INDEX(Calc!$B$2:$BB$61,AE31,0),">="&$C$6,INDEX(Calc!$B$2:$BB$61,AE31,0),"<"&($C$7+1))*INDEX(Setup!$E$25:$E$84,AE31)) | N31: =IF(L31="","",SUMIFS(Payments!$Q$6:$Q$1205,Payments!$I$6:$I$1205,"Bills",Payments!$E$6:$E$1205,L31,Payments!$P$6:$P$1205,">="&$C$6,Payments!$P$6:$P$1205,"<="&$C$7)+SUMIFS('Manual Log'!$E$6:$E$1005,'Manual Log'!$C$6:$C$1005,"Bills",'Manual Log'!$D$6:$D$1005,L31,'Manual Log'!$B$6:$B$1005,">="&$C$6,'Manual Log'!$B$6:$B$1005,"<="&$C$7)) | O31: =IF(L31="","",M31-N31) | Q31: =IF(AF31="","",INDEX(Setup!$D$25:$D$84,AF31)) | R31: =IF(AF31="","",COUNTIFS(INDEX(Calc!$B$2:$BB$61,AF31,0),">="&$C$6,INDEX(Calc!$B$2:$BB$61,AF31,0),"<"&($C$7+1))*INDEX(Setup!$E$25:$E$84,AF31)) | S31: =IF(Q31="","",SUMIFS(Payments!$Q$6:$Q$1205,Payments!$I$6:$I$1205,"Debt",Payments!$E$6:$E$1205,Q31,Payments!$P$6:$P$1205,">="&$C$6,Payments!$P$6:$P$1205,"<="&$C$7)+SUMIFS('Manual Log'!$E$6:$E$1005,'Manual Log'!$C$6:$C$1005,"Debt",'Manual Log'!$D$6:$D$1005,Q31,'Manual Log'!$B$6:$B$1005,">="&$C$6,'Manual Log'!$B$6:$B$1005,"<="&$C$7)) | T31: =IF(Q31="","",R31-S31) | V31: =IF($C$6+0*$V$29>$C$7,"",$C$6+0*$V$29) | W31: =IF(V31="","",SUMIFS(Payments!$Q$6:$Q$1205,Payments!$I$6:$I$1205,"<>Income",Payments!$I$6:$I$1205,"<>Savings",Payments!$P$6:$P$1205,">="&V31,Payments!$P$6:$P$1205,"<"&(V31+$V$29),Payments!$P$6:$P$1205,"<="&$C$7)+SUMIFS('Manual Log'!$E$6:$E$1005,'Manual Log'!$C$6:$C$1005,"<>Income",'Manual Log'!$C$6:$C$1005,"<>Savings",'Manual Log'!$C$6:$C$1005,"<>Transfer",'Manual Log'!$B$6:$B$1005,">="&V31,'Manual Log'!$B$6:$B$1005,"<"&(V31+$V$29),'Manual Log'!$B$6:$B$1005,"<="&$C$7)) | X31: =IF(V31="","",TEXT(V31,"ddd d mmm")) | Y31: =L31 | Z31: =N31 | AA31: =IF(OR(Y31="",N(Z31)<=0),"",Z31+ROW()/1000000) | AC31: =IFERROR(MATCH("Income|1",Setup!$L$25:$L$84,0),"") | AD31: =IFERROR(MATCH("Savings|1",Setup!$L$25:$L$84,0),"") | AE31: =IFERROR(MATCH("Bills|1",Setup!$L$25:$L$84,0),"") | AF31: =IFERROR(MATCH("Debt|1",Setup!$L$25:$L$84,0),"")
